Workbook

Sheet 使い方
B1: 進捗管理シート 使い方
B3: 概要
B4: タスクの依存関係(先行タスク)と所要日数から、各タスクの計画開始日・終了日・クリティカルパスを自動計算します。
B5: 「タスク一覧」シートに入力するだけで、他のシートは自動的に更新されます。
B8: ■ シート構成
B9: 設定
B10: プロジェクト開始日を入力します(黄色セル)。終了予定日は自動計算されます。
B11: マイルストーン一覧
B12: マイルストーン名と期限を登録します。「タスク一覧」のプルダウンに反映されます。
B13: 担当者一覧
B14: 担当者名を登録します。「タスク一覧」のプルダウンに反映されます。
B15: タスク一覧
... B56: ■ 今後について

Sheet 設定
A1: プロジェクト設定
A2: プロジェクト開始日 | B2: 46237 | C2: ★ここを編集してください(最初のタスクの着手日)
A3: プロジェクト終了予定日(自動計算) | B3: =IFERROR(MAX(タスク一覧!$L$3:$L$102),"") -> 46280 | C3: 全タスクの計画終了日のうち、最も遅い日付(=クリティカルパスの完了日)
A4: 本日 | B4: =TODAY() -> 46227

Sheet マイルストーン一覧
A1: マイルストーン一覧
A2: ID | B2: マイルストーン名 | C2: 期限 | D2: 備考
A3: M1 | B3: 要件定義完了 | C3: 46248 | D3: サンプル
A4: M2 | B4: 設計完了 | C4: 46276 | D4: サンプル
A5: M3 | B5: リリース | C5: 46304 | D5: サンプル
A15: ※ 3行目以降に自由に追加してください(空欄不可・IDは一意にしてください)。「タスク一覧」のマイルストーン欄のプルダウンはB3:B12を参照しています。

Sheet 担当者一覧
A1: 担当者一覧
A2: ID | B2: 氏名 | C2: 備考
A3: A1 | B3: 担当者A(例) | C3: サンプル。実際の氏名に置き換えてください
A4: A2 | B4: 担当者B(例) | C4: サンプル。実際の氏名に置き換えてください
A5: A3 | B5: 担当者C(例) | C5: サンプル。実際の氏名に置き換えてください
A15: ※ 3行目以降に自由に追加してください。「タスク一覧」の担当者欄のプルダウンはB3:B12を参照しています。

Sheet タスク一覧
A1: タスク一覧
A2: ID | B2: 親タスクID (サブタスク用) | C2: タスク名 | D2: マイルストーン | E2: 担当者 | F2: 先行 タスク1 | G2: 先行 タスク2 | H2: 先行 タスク3 | I2: 所要日数 (営業日) | J2: ステータス | K2: 計画開始日 (自動計算) | L2: 計画終了日 (自動計算) | M2: 最遅開始日 (自動計算) | N2: 最遅終了日 (自動計算) | O2: 余裕日数 (自動計算) | P2: クリティカル パス | Q2: 遅延 | R2: ブロック要因 (自動計算) | S2: 残タスク (1/0)
A3: 1 | C3: 要件ヒアリング | D3: 要件定義完了 | E3: 担当者A(例) | I3: 3 | J3: 完了 | K3: =IF($A3="","",設定!$B$2) -> 46237 | L3: =IF($A3="","",WORKDAY($K3,$I3-1)) -> 46239 | M3: =IF($A3="","",WORKDAY($N3,-($I3-1))) -> 46237 | N3: =IF($A3="","",IF(COUNTIF($F$4:$F$102,$A3)+COUNTIF($G$4:$G$102,$A3)+COUNTIF($H$4:$H$102,$A3)=0,設定!$B$3,MIN(IF(COUNTIF($F$4:$F$102,$A3)=0,999999,IFERROR(WORKDAY(_xlfn.MINIFS($M$4:$M$102,$F$4:$F$102,$A3),-1),999999)),IF(COUNTIF($G$4:$G$102,$A3)=0,999999,IFERROR(WORKDAY(_xlfn.MINIFS($M$4:$M$102,$G$4:$G$102,$A3),-1),999999)),IF(COUNTIF($H$4:$H$102,$A3)=0,999999,IFERROR(WORKDAY(_xlfn.MINIFS($M$4:$M$102,$H$4:$H$102,$A3),-1),999999))))) -> 46239 | O3: =IF($A3="","",NETWORKDAYS($K3,$M3)-1) -> 0 | P3: =IF($A3="","",IF($O3<=0,"クリティカル","")) -> クリティカル | Q3: =IF($A3="","",IF(AND($J3<>"完了",TODAY()>$L3),"遅延","")) | R3: =IF($A3="","",_xlfn.TEXTJOIN(", ",TRUE(),IF($F3="","",IF(IFERROR(INDEX($J$3:$J$102,MATCH($F3,$A$3:$A$102,0)),"")<>"完了",IFERROR(INDEX($C$3:$C$102,MATCH($F3,$A$3:$A$102,0)),""),"")),IF($G3="","",IF(IFERROR(INDEX($J$3:$J$102,MATCH($G3,$A$3:$A$102,0)),"")<>"完了",IFERROR(INDEX($C$3:$C$102,MATCH($G3,$A$3:$A$102,0)),""),"")),IF($H3="","",IF(IFERROR(INDEX($J$3:$J$102,MATCH($H3,$A$3:$A$102,0)),"")<>"完了",IFERROR(INDEX($C$3:$C$102,MATCH($H3,$A$3:$A$102,0)),""),"")))) | S3: =IF($A3="","",IF($J3<>"完了",1,0)) -> 0
A4: 2 | C4: 要件定義書作成 | D4: 要件定義完了 | E4: 担当者A(例) | F4: 1 | I4: 4 | J4: 完了 | K4: =IF($A4="","",IF(AND($F4="",$G4="",$H4=""),設定!$B$2,MAX(IF($F4="",0,IFERROR(WORKDAY(INDEX($L$3:$L$3,MATCH($F4,$A$3:$A$3,0)),1),0)),IF($G4="",0,IFERROR(WORKDAY(INDEX($L$3:$L$3,MATCH($G4,$A$3:$A$3,0)),1),0)),IF($H4="",0,IFERROR(WORKDAY(INDEX($L$3:$L$3,MATCH($H4,$A$3:$A$3,0)),1),0))))) -> 46240 | L4: =IF($A4="","",WORKDAY($K4,$I4-1)) -> 46245 | M4: =IF($A4="","",WORKDAY($N4,-($I4-1))) -> 46240 | N4: =IF($A4="","",IF(COUNTIF($F$5:$F$102,$A4)+COUNTIF($G$5:$G$102,$A4)+COUNTIF($H$5:$H$102,$A4)=0,設定!$B$3,MIN(IF(COUNTIF($F$5:$F$102,$A4)=0,999999,IFERROR(WORKDAY(_xlfn.MINIFS($M$5:$M$102,$F$5:$F$102,$A4),-1),999999)),IF(COUNTIF($G$5:$G$102,$A4)=0,999999,IFERROR(WORKDAY(_xlfn.MINIFS($M$5:$M$102,$G$5:$G$102,$A4),-1),999999)),IF(COUNTIF($H$5:$H$102,$A4)=0,999999,IFERROR(WORKDAY(_xlfn.MINIFS($M$5:$M$102,$H$5:$H$102,$A4),-1),999999))))) -> 46245 | O4: =IF($A4="","",NETWORKDAYS($K4,$M4)-1) -> 0 | P4: =IF($A4="","",IF($O4<=0,"クリティカル","")) -> クリティカル | Q4: =IF($A4="","",IF(AND($J4<>"完了",TODAY()>$L4),"遅延","")) | R4: =IF($A4="","",_xlfn.TEXTJOIN(", ",TRUE(),IF($F4="","",IF(IFERROR(INDEX($J$3:$J$102,MATCH($F4,$A$3:$A$102,0)),"")<>"完了",IFERROR(INDEX($C$3:$C$102,MATCH($F4,$A$3:$A$102,0)),""),"")),IF($G4="","",IF(IFERROR(INDEX($J$3:$J$102,MATCH($G4,$A$3:$A$102,0)),"")<>"完了",IFERROR(INDEX($C$3:$C$102,MATCH($G4,$A$3:$A$102,0)),""),"")),IF($H4="","",IF(IFERROR(INDEX($J$3:$J$102,MATCH($H4,$A$3:$A$102,0)),"")<>"完了",IFERROR(INDEX($C$3:$C$102,MATCH($H4,$A$3:$A$102,0)),""),"")))) | S4: =IF($A4="","",IF($J4<>"完了",1,0)) -> 0
A5: 3 | C5: 要件レビュー | D5: 要件定義完了 | E5: 担当者B(例) | F5: 2 | I5: 2 | J5: 進行中 | K5: =IF($A5="","",IF(AND($F5="",$G5="",$H5=""),設定!$B$2,MAX(IF($F5="",0,IFERROR(WORKDAY(INDEX($L$3:$L$4,MATCH($F5,$A$3:$A$4,0)),1),0)),IF($G5="",0,IFERROR(WORKDAY(INDEX($L$3:$L$4,MATCH($G5,$A$3:$A$4,0)),1),0)),IF($H5="",0,IFERROR(WORKDAY(INDEX($L$3:$L$4,MATCH($H5,$A$3:$A$4,0)),1),0))))) -> 46246 | L5: =IF($A5="","",WORKDAY($K5,$I5-1)) -> 46247 | M5: =IF($A5="","",WORKDAY($N5,-($I5-1))) -> 46246 | N5: =IF($A5="","",IF(COUNTIF($F$6:$F$102,$A5)+COUNTIF($G$6:$G$102,$A5)+COUNTIF($H$6:$H$102,$A5)=0,設定!$B$3,MIN(IF(COUNTIF($F$6:$F$102,$A5)=0,999999,IFERROR(WORKDAY(_xlfn.MINIFS($M$6:$M$102,$F$6:$F$102,$A5),-1),999999)),IF(COUNTIF($G$6:$G$102,$A5)=0,999999,IFERROR(WORKDAY(_xlfn.MINIFS($M$6:$M$102,$G$6:$G$102,$A5),-1),999999)),IF(COUNTIF($H$6:$H$102,$A5)=0,999999,IFERROR(WORKDAY(_xlfn.MINIFS($M$6:$M$102,$H$6:$H$102,$A5),-1),999999))))) -> 46247 | O5: =IF($A5="","",NETWORKDAYS($K5,$M5)-1) -> 0 | P5: =IF($A5="","",IF($O5<=0,"クリティカル","")) -> クリティカル | Q5: =IF($A5="","",IF(AND($J5<>"完了",TODAY()>$L5),"遅延","")) | R5: =IF($A5="","",_xlfn.TEXTJOIN(", ",TRUE(),IF($F5="","",IF(IFERROR(INDEX($J$3:$J$102,MATCH($F5,$A$3:$A$102,0)),"")<>"完了",IFERROR(INDEX($C$3:$C$102,MATCH($F5,$A$3:$A$102,0)),""),"")),IF($G5="","",IF(IFERROR(INDEX($J$3:$J$102,MATCH($G5,$A$3:$A$102,0)),"")<>"完了",IFERROR(INDEX($C$3:$C$102,MATCH($G5,$A$3:$A$102,0)),""),"")),IF($H5="","",IF(IFERROR(INDEX($J$3:$J$102,MATCH($H5,$A$3:$A$102,0)),"")<>"完了",IFERROR(INDEX($C$3:$C$102,MATCH($H5,$A$3:$A$102,0)),""),"")))) | S5: =IF($A5="","",IF($J5<>"完了",1,0)) -> 1
A6: 4 | C6: 画面設計 | D6: 設計完了 | E6: 担当者B(例) | F6: 3 | I6: 5 | J6: 未着手 | K6: =IF($A6="","",IF(AND($F6="",$G6="",$H6=""),設定!$B$2,MAX(IF($F6="",0,IFERROR(WORKDAY(INDEX($L$3:$L$5,MATCH($F6,$A$3:$A$5,0)),1),0)),IF($G6="",0,IFERROR(WORKDAY(INDEX($L$3:$L$5,MATCH($G6,$A$3:$A$5,0)),1),0)),IF($H6="",0,IFERROR(WORKDAY(INDEX($L$3:$L$5,MATCH($H6,$A$3:$A$5,0)),1),0))))) -> 46248 | L6: =IF($A6="","",WORKDAY($K6,$I6-1)) -> 46254 | M6: =IF($A6="","",WORKDAY($N6,-($I6-1))) -> 46253 | N6: =IF($A6="","",IF(COUNTIF($F$7:$F$102,$A6)+COUNTIF($G$7:$G$102,$A6)+COUNTIF($H$7:$H$102,$A6)=0,設定!$B$3,MIN(IF(COUNTIF($F$7:$F$102,$A6)=0,999999,IFERROR(WORKDAY(_xlfn.MINIFS($M$7:$M$102,$F$7:$F$102,$A6),-1),999999)),IF(COUNTIF($G$7:$G$102,$A6)=0,999999,IFERROR(WORKDAY(_xlfn.MINIFS($M$7:$M$102,$G$7:$G$102,$A6),-1),999999)),IF(COUNTIF($H$7:$H$102,$A6)=0,999999,IFERROR(WORKDAY(_xlfn.MINIFS($M$7:$M$102,$H$7:$H$102,$A6),-1),999999))))) -> 46259 | O6: =IF($A6="","",NETWORKDAYS($K6,$M6)-1) -> 3 | P6: =IF($A6="","",IF($O6<=0,"クリティカル","")) | Q6: =IF($A6="","",IF(AND($J6<>"完了",TODAY()>$L6),"遅延","")) | R6: =IF($A6="","",_xlfn.TEXTJOIN(", ",TRUE(),IF($F6="","",IF(IFERROR(INDEX($J$3:$J$102,MATCH($F6,$A$3:$A$102,0)),"")<>"完了",IFERROR(INDEX($C$3:$C$102,MATCH($F6,$A$3:$A$102,0)),""),"")),IF($G6="","",IF(IFERROR(INDEX($J$3:$J$102,MATCH($G6,$A$3:$A$102,0)),"")<>"完了",IFERROR(INDEX($C$3:$C$102,MATCH($G6,$A$3:$A$102,0)),""),"")),IF($H6="","",IF(IFERROR(INDEX($J$3:$J$102,MATCH($H6,$A$3:$A$102,0)),"")<>"完了",IFERROR(INDEX($C$3:$C$102,MATCH($H6,$A$3:$A$102,0)),""),"")))) -> 要件レビュー | S6: =IF($A6="","",IF($J6<>"完了",1,0)) -> 1
A7: 5 | C7: DB設計 | D7: 設計完了 | E7: 担当者C(例) | F7: 3 | I7: 5 | J7: 未着手 | K7: =IF($A7="","",IF(AND($F7="",$G7="",$H7=""),設定!$B$2,MAX(IF($F7="",0,IFERROR(WORKDAY(INDEX($L$3:$L$6,MATCH($F7,$A$3:$A$6,0)),1),0)),IF($G7="",0,IFERROR(WORKDAY(INDEX($L$3:$L$6,MATCH($G7,$A$3:$A$6,0)),1),0)),IF($H7="",0,IFERROR(WORKDAY(INDEX($L$3:$L$6,MATCH($H7,$A$3:$A$6,0)),1),0))))) -> 46248 | L7: =IF($A7="","",WORKDAY($K7,$I7-1)) -> 46254 | M7: =IF($A7="","",WORKDAY($N7,-($I7-1))) -> 46248 | N7: =IF($A7="","",IF(COUNTIF($F$8:$F$102,$A7)+COUNTIF($G$8:$G$102,$A7)+COUNTIF($H$8:$H$102,$A7)=0,設定!$B$3,MIN(IF(COUNTIF($F$8:$F$102,$A7)=0,999999,IFERROR(WORKDAY(_xlfn.MINIFS($M$8:$M$102,$F$8:$F$102,$A7),-1),999999)),IF(COUNTIF($G$8:$G$102,$A7)=0,999999,IFERROR(WORKDAY(_xlfn.MINIFS($M$8:$M$102,$G$8:$G$102,$A7),-1),999999)),IF(COUNTIF($H$8:$H$102,$A7)=0,999999,IFERROR(WORKDAY(_xlfn.MINIFS($M$8:$M$102,$H$8:$H$102,$A7),-1),999999))))) -> 46254 | O7: =IF($A7="","",NETWORKDAYS($K7,$M7)-1) -> 0 | P7: =IF($A7="","",IF($O7<=0,"クリティカル","")) -> クリティカル | Q7: =IF($A7="","",IF(AND($J7<>"完了",TODAY()>$L7),"遅延","")) | R7: =IF($A7="","",_xlfn.TEXTJOIN(", ",TRUE(),IF($F7="","",IF(IFERROR(INDEX($J$3:$J$102,MATCH($F7,$A$3:$A$102,0)),"")<>"完了",IFERROR(INDEX($C$3:$C$102,MATCH($F7,$A$3:$A$102,0)),""),"")),IF($G7="","",IF(IFERROR(INDEX($J$3:$J$102,MATCH($G7,$A$3:$A$102,0)),"")<>"完了",IFERROR(INDEX($C$3:$C$102,MATCH($G7,$A$3:$A$102,0)),""),"")),IF($H7="","",IF(IFERROR(INDEX($J$3:$J$102,MATCH($H7,$A$3:$A$102,0)),"")<>"完了",IFERROR(INDEX($C$3:$C$102,MATCH($H7,$A$3:$A$102,0)),""),"")))) -> 要件レビュー | S7: =IF($A7="","",IF($J7<>"完了",1,0)) -> 1
A8: 6 | C8: API設計 | D8: 設計完了 | E8: 担当者C(例) | F8: 5 | I8: 3 | J8: 未着手 | K8: =IF($A8="","",IF(AND($F8="",$G8="",$H8=""),設定!$B$2,MAX(IF($F8="",0,IFERROR(WORKDAY(INDEX($L$3:$L$7,MATCH($F8,$A$3:$A$7,0)),1),0)),IF($G8="",0,IFERROR(WORKDAY(INDEX($L$3:$L$7,MATCH($G8,$A$3:$A$7,0)),1),0)),IF($H8="",0,IFERROR(WORKDAY(INDEX($L$3:$L$7,MATCH($H8,$A$3:$A$7,0)),1),0))))) -> 46255 | L8: =IF($A8="","",WORKDAY($K8,$I8-1)) -> 46259 | M8: =IF($A8="","",WORKDAY($N8,-($I8-1))) -> 46255 | N8: =IF($A8="","",IF(COUNTIF($F$9:$F$102,$A8)+COUNTIF($G$9:$G$102,$A8)+COUNTIF($H$9:$H$102,$A8)=0,設定!$B$3,MIN(IF(COUNTIF($F$9:$F$102,$A8)=0,999999,IFERROR(WORKDAY(_xlfn.MINIFS($M$9:$M$102,$F$9:$F$102,$A8),-1),999999)),IF(COUNTIF($G$9:$G$102,$A8)=0,999999,IFERROR(WORKDAY(_xlfn.MINIFS($M$9:$M$102,$G$9:$G$102,$A8),-1),999999)),IF(COUNTIF($H$9:$H$102,$A8)=0,999999,IFERROR(WORKDAY(_xlfn.MINIFS($M$9:$M$102,$H$9:$H$102,$A8),-1),999999))))) -> 46259 | O8: =IF($A8="","",NETWORKDAYS($K8,$M8)-1) -> 0 | P8: =IF($A8="","",IF($O8<=0,"クリティカル","")) -> クリティカル | Q8: =IF($A8="","",IF(AND($J8<>"完了",TODAY()>$L8),"遅延","")) | R8: =IF($A8="","",_xlfn.TEXTJOIN(", ",TRUE(),IF($F8="","",IF(IFERROR(INDEX($J$3:$J$102,MATCH($F8,$A$3:$A$102,0)),"")<>"完了",IFERROR(INDEX($C$3:$C$102,MATCH($F8,$A$3:$A$102,0)),""),"")),IF($G8="","",IF(IFERROR(INDEX($J$3:$J$102,MATCH($G8,$A$3:$A$102,0)),"")<>"完了",IFERROR(INDEX($C$3:$C$102,MATCH($G8,$A$3:$A$102,0)),""),"")),IF($H8="","",IF(IFERROR(INDEX($J$3:$J$102,MATCH($H8,$A$3:$A$102,0)),"")<>"完了",IFERROR(INDEX($C$3:$C$102,MATCH($H8,$A$3:$A$102,0)),""),"")))) -> DB設計 | S8: =IF($A8="","",IF($J8<>"完了",1,0)) -> 1
A9: 7 | C9: 設計レビュー | D9: 設計完了 | E9: 担当者B(例) | F9: 4 | G9: 6 | I9: 2 | J9: 未着手 | K9: =IF($A9="","",IF(AND($F9="",$G9="",$H9=""),設定!$B$2,MAX(IF($F9="",0,IFERROR(WORKDAY(INDEX($L$3:$L$8,MATCH($F9,$A$3:$A$8,0)),1),0)),IF($G9="",0,IFERROR(WORKDAY(INDEX($L$3:$L$8,MATCH($G9,$A$3:$A$8,0)),1),0)),IF($H9="",0,IFERROR(WORKDAY(INDEX($L$3:$L$8,MATCH($H9,$A$3:$A$8,0)),1),0))))) -> 46260 | L9: =IF($A9="","",WORKDAY($K9,$I9-1)) -> 46261 | M9: =IF($A9="","",WORKDAY($N9,-($I9-1))) -> 46260 | N9: =IF($A9="","",IF(COUNTIF($F$10:$F$102,$A9)+COUNTIF($G$10:$G$102,$A9)+COUNTIF($H$10:$H$102,$A9)=0,設定!$B$3,MIN(IF(COUNTIF($F$10:$F$102,$A9)=0,999999,IFERROR(WORKDAY(_xlfn.MINIFS($M$10:$M$102,$F$10:$F$102,$A9),-1),999999)),IF(COUNTIF($G$10:$G$102,$A9)=0,999999,IFERROR(WORKDAY(_xlfn.MINIFS($M$10:$M$102,$G$10:$G$102,$A9),-1),999999)),IF(COUNTIF($H$10:$H$102,$A9)=0,999999,IFERROR(WORKDAY(_xlfn.MINIFS($M$10:$M$102,$H$10:$H$102,$A9),-1),999999))))) -> 46261 | O9: =IF($A9="","",NETWORKDAYS($K9,$M9)-1) -> 0 | P9: =IF($A9="","",IF($O9<=0,"クリティカル","")) -> クリティカル | Q9: =IF($A9="","",IF(AND($J9<>"完了",TODAY()>$L9),"遅延","")) | R9: =IF($A9="","",_xlfn.TEXTJOIN(", ",TRUE(),IF($F9="","",IF(IFERROR(INDEX($J$3:$J$102,MATCH($F9,$A$3:$A$102,0)),"")<>"完了",IFERROR(INDEX($C$3:$C$102,MATCH($F9,$A$3:$A$102,0)),""),"")),IF($G9="","",IF(IFERROR(INDEX($J$3:$J$102,MATCH($G9,$A$3:$A$102,0)),"")<>"完了",IFERROR(INDEX($C$3:$C$102,MATCH($G9,$A$3:$A$102,0)),""),"")),IF($H9="","",IF(IFERROR(INDEX($J$3:$J$102,MATCH($H9,$A$3:$A$102,0)),"")<>"完了",IFERROR(INDEX($C$3:$C$102,MATCH($H9,$A$3:$A$102,0)),""),"")))) -> 画面設計, API設計 | S9: =IF($A9="","",IF($J9<>"完了",1,0)) -> 1
A10: 8 | C10: 実装 | D10: リリース | E10: 担当者A(例) | F10: 7 | I10: 8 | J10: 未着手 | K10: =IF($A10="","",IF(AND($F10="",$G10="",$H10=""),設定!$B$2,MAX(IF($F10="",0,IFERROR(WORKDAY(INDEX($L$3:$L$9,MATCH($F10,$A$3:$A$9,0)),1),0)),IF($G10="",0,IFERROR(WORKDAY(INDEX($L$3:$L$9,MATCH($G10,$A$3:$A$9,0)),1),0)),IF($H10="",0,IFERROR(WORKDAY(INDEX($L$3:$L$9,MATCH($H10,$A$3:$A$9,0)),1),0))))) -> 46262 | L10: =IF($A10="","",WORKDAY($K10,$I10-1)) -> 46273 | M10: =IF($A10="","",WORKDAY($N10,-($I10-1))) -> 46262 | N10: =IF($A10="","",IF(COUNTIF($F$11:$F$102,$A10)+COUNTIF($G$11:$G$102,$A10)+COUNTIF($H$11:$H$102,$A10)=0,設定!$B$3,MIN(IF(COUNTIF($F$11:$F$102,$A10)=0,999999,IFERROR(WORKDAY(_xlfn.MINIFS($M$11:$M$102,$F$11:$F$102,$A10),-1),999999)),IF(COUNTIF($G$11:$G$102,$A10)=0,999999,IFERROR(WORKDAY(_xlfn.MINIFS($M$11:$M$102,$G$11:$G$102,$A10),-1),999999)),IF(COUNTIF($H$11:$H$102,$A10)=0,999999,IFERROR(WORKDAY(_xlfn.MINIFS($M$11:$M$102,$H$11:$H$102,$A10),-1),999999))))) -> 46273 | O10: =IF($A10="","",NETWORKDAYS($K10,$M10)-1) -> 0 | P10: =IF($A10="","",IF($O10<=0,"クリティカル","")) -> クリティカル | Q10: =IF($A10="","",IF(AND($J10<>"完了",TODAY()>$L10),"遅延","")) | R10: =IF($A10="","",_xlfn.TEXTJOIN(", ",TRUE(),IF($F10="","",IF(IFERROR(INDEX($J$3:$J$102,MATCH($F10,$A$3:$A$102,0)),"")<>"完了",IFERROR(INDEX($C$3:$C$102,MATCH($F10,$A$3:$A$102,0)),""),"")),IF($G10="","",IF(IFERROR(INDEX($J$3:$J$102,MATCH($G10,$A$3:$A$102,0)),"")<>"完了",IFERROR(INDEX($C$3:$C$102,MATCH($G10,$A$3:$A$102,0)),""),"")),IF($H10="","",IF(IFERROR(INDEX($J$3:$J$102,MATCH($H10,$A$3:$A$102,0)),"")<>"完了",IFERROR(INDEX($C$3:$C$102,MATCH($H10,$A$3:$A$102,0)),""),"")))) -> 設計レビュー | S10: =IF($A10="","",IF($J10<>"完了",1,0)) -> 1
A11: 8.1 | B11: 8 | C11: 実装(画面) | D11: リリース | E11: 担当者A(例) | I11: 4 | J11: 未着手 | K11: =IF($A11="","",IF(AND($F11="",$G11="",$H11=""),設定!$B$2,MAX(IF($F11="",0,IFERROR(WORKDAY(INDEX($L$3:$L$10,MATCH($F11,$A$3:$A$10,0)),1),0)),IF($G11="",0,IFERROR(WORKDAY(INDEX($L$3:$L$10,MATCH($G11,$A$3:$A$10,0)),1),0)),IF($H11="",0,IFERROR(WORKDAY(INDEX($L$3:$L$10,MATCH($H11,$A$3:$A$10,0)),1),0))))) -> 46237 | L11: =IF($A11="","",WORKDAY($K11,$I11-1)) -> 46240 | M11: =IF($A11="","",WORKDAY($N11,-($I11-1))) -> 46275 | N11: =IF($A11="","",IF(COUNTIF($F$12:$F$102,$A11)+COUNTIF($G$12:$G$102,$A11)+COUNTIF($H$12:$H$102,$A11)=0,設定!$B$3,MIN(IF(COUNTIF($F$12:$F$102,$A11)=0,999999,IFERROR(WORKDAY(_xlfn.MINIFS($M$12:$M$102,$F$12:$F$102,$A11),-1),999999)),IF(COUNTIF($G$12:$G$102,$A11)=0,999999,IFERROR(WORKDAY(_xlfn.MINIFS($M$12:$M$102,$G$12:$G$102,$A11),-1),999999)),IF(COUNTIF($H$12:$H$102,$A11)=0,999999,IFERROR(WORKDAY(_xlfn.MINIFS($M$12:$M$102,$H$12:$H$102,$A11),-1),999999))))) -> 46280 | O11: =IF($A11="","",NETWORKDAYS($K11,$M11)-1) -> 28 | P11: =IF($A11="","",IF($O11<=0,"クリティカル","")) | Q11: =IF($A11="","",IF(AND($J11<>"完了",TODAY()>$L11),"遅延","")) | R11: =IF($A11="","",_xlfn.TEXTJOIN(", ",TRUE(),IF($F11="","",IF(IFERROR(INDEX($J$3:$J$102,MATCH($F11,$A$3:$A$102,0)),"")<>"完了",IFERROR(INDEX($C$3:$C$102,MATCH($F11,$A$3:$A$102,0)),""),"")),IF($G11="","",IF(IFERROR(INDEX($J$3:$J$102,MATCH($G11,$A$3:$A$102,0)),"")<>"完了",IFERROR(INDEX($C$3:$C$102,MATCH($G11,$A$3:$A$102,0)),""),"")),IF($H11="","",IF(IFERROR(INDEX($J$3:$J$102,MATCH($H11,$A$3:$A$102,0)),"")<>"完了",IFERROR(INDEX($C$3:$C$102,MATCH($H11,$A$3:$A$102,0)),""),"")))) | S11: =IF($A11="","",IF($J11<>"完了",1,0)) -> 1
A12: 9 | C12: テスト | D12: リリース | E12: 担当者B(例) | F12: 8 | I12: 4 | J12: 未着手 | K12: =IF($A12="","",IF(AND($F12="",$G12="",$H12=""),設定!$B$2,MAX(IF($F12="",0,IFERROR(WORKDAY(INDEX($L$3:$L$11,MATCH($F12,$A$3:$A$11,0)),1),0)),IF($G12="",0,IFERROR(WORKDAY(INDEX($L$3:$L$11,MATCH($G12,$A$3:$A$11,0)),1),0)),IF($H12="",0,IFERROR(WORKDAY(INDEX($L$3:$L$11,MATCH($H12,$A$3:$A$11,0)),1),0))))) -> 46274 | L12: =IF($A12="","",WORKDAY($K12,$I12-1)) -> 46279 | M12: =IF($A12="","",WORKDAY($N12,-($I12-1))) -> 46274 | N12: =IF($A12="","",IF(COUNTIF($F$13:$F$102,$A12)+COUNTIF($G$13:$G$102,$A12)+COUNTIF($H$13:$H$102,$A12)=0,設定!$B$3,MIN(IF(COUNTIF($F$13:$F$102,$A12)=0,999999,IFERROR(WORKDAY(_xlfn.MINIFS($M$13:$M$102,$F$13:$F$102,$A12),-1),999999)),IF(COUNTIF($G$13:$G$102,$A12)=0,999999,IFERROR(WORKDAY(_xlfn.MINIFS($M$13:$M$102,$G$13:$G$102,$A12),-1),999999)),IF(COUNTIF($H$13:$H$102,$A12)=0,999999,IFERROR(WORKDAY(_xlfn.MINIFS($M$13:$M$102,$H$13:$H$102,$A12),-1),999999))))) -> 46279 | O12: =IF($A12="","",NETWORKDAYS($K12,$M12)-1) -> 0 | P12: =IF($A12="","",IF($O12<=0,"クリティカル","")) -> クリティカル | Q12: =IF($A12="","",IF(AND($J12<>"完了",TODAY()>$L12),"遅延","")) | R12: =IF($A12="","",_xlfn.TEXTJOIN(", ",TRUE(),IF($F12="","",IF(IFERROR(INDEX($J$3:$J$102,MATCH($F12,$A$3:$A$102,0)),"")<>"完了",IFERROR(INDEX($C$3:$C$102,MATCH($F12,$A$3:$A$102,0)),""),"")),IF($G12="","",IF(IFERROR(INDEX($J$3:$J$102,MATCH($G12,$A$3:$A$102,0)),"")<>"完了",IFERROR(INDEX($C$3:$C$102,MATCH($G12,$A$3:$A$102,0)),""),"")),IF($H12="","",IF(IFERROR(INDEX($J$3:$J$102,MATCH($H12,$A$3:$A$102,0)),"")<>"完了",IFERROR(INDEX($C$3:$C$102,MATCH($H12,$A$3:$A$102,0)),""),"")))) -> 実装 | S12: =IF($A12="","",IF($J12<>"完了",1,0)) -> 1
A13: 10 | C13: リリース判定 | D13: リリース | E13: 担当者C(例) | F13: 9 | I13: 1 | J13: 未着手 | K13: =IF($A13="","",IF(AND($F13="",$G13="",$H13=""),設定!$B$2,MAX(IF($F13="",0,IFERROR(WORKDAY(INDEX($L$3:$L$12,MATCH($F13,$A$3:$A$12,0)),1),0)),IF($G13="",0,IFERROR(WORKDAY(INDEX($L$3:$L$12,MATCH($G13,$A$3:$A$12,0)),1),0)),IF($H13="",0,IFERROR(WORKDAY(INDEX($L$3:$L$12,MATCH($H13,$A$3:$A$12,0)),1),0))))) -> 46280 | L13: =IF($A13="","",WORKDAY($K13,$I13-1)) -> 46280 | M13: =IF($A13="","",WORKDAY($N13,-($I13-1))) -> 46280 | N13: =IF($A13="","",IF(COUNTIF($F$14:$F$102,$A13)+COUNTIF($G$14:$G$102,$A13)+COUNTIF($H$14:$H$102,$A13)=0,設定!$B$3,MIN(IF(COUNTIF($F$14:$F$102,$A13)=0,999999,IFERROR(WORKDAY(_xlfn.MINIFS($M$14:$M$102,$F$14:$F$102,$A13),-1),999999)),IF(COUNTIF($G$14:$G$102,$A13)=0,999999,IFERROR(WORKDAY(_xlfn.MINIFS($M$14:$M$102,$G$14:$G$102,$A13),-1),999999)),IF(COUNTIF($H$14:$H$102,$A13)=0,999999,IFERROR(WORKDAY(_xlfn.MINIFS($M$14:$M$102,$H$14:$H$102,$A13),-1),999999))))) -> 46280 | O13: =IF($A13="","",NETWORKDAYS($K13,$M13)-1) -> 0 | P13: =IF($A13="","",IF($O13<=0,"クリティカル","")) -> クリティカル | Q13: =IF($A13="","",IF(AND($J13<>"完了",TODAY()>$L13),"遅延","")) | R13: =IF($A13="","",_xlfn.TEXTJOIN(", ",TRUE(),IF($F13="","",IF(IFERROR(INDEX($J$3:$J$102,MATCH($F13,$A$3:$A$102,0)),"")<>"完了",IFERROR(INDEX($C$3:$C$102,MATCH($F13,$A$3:$A$102,0)),""),"")),IF($G13="","",IF(IFERROR(INDEX($J$3:$J$102,MATCH($G13,$A$3:$A$102,0)),"")<>"完了",IFERROR(INDEX($C$3:$C$102,MATCH($G13,$A$3:$A$102,0)),""),"")),IF($H13="","",IF(IFERROR(INDEX($J$3:$J$102,MATCH($H13,$A$3:$A$102,0)),"")<>"完了",IFERROR(INDEX($C$3:$C$102,MATCH($H13,$A$3:$A$102,0)),""),"")))) -> テスト | S13: =IF($A13="","",IF($J13<>"完了",1,0)) -> 1
K14: =IF($A14="","",IF(AND($F14="",$G14="",$H14=""),設定!$B$2,MAX(IF($F14="",0,IFERROR(WORKDAY(INDEX($L$3:$L$13,MATCH($F14,$A$3:$A$13,0)),1),0)),IF($G14="",0,IFERROR(WORKDAY(INDEX($L$3:$L$13,MATCH($G14,$A$3:$A$13,0)),1),0)),IF($H14="",0,IFERROR(WORKDAY(INDEX($L$3:$L$13,MATCH($H14,$A$3:$A$13,0)),1),0))))) | L14: =IF($A14="","",WORKDAY($K14,$I14-1)) | M14: =IF($A14="","",WORKDAY($N14,-($I14-1))) | N14: =IF($A14="","",IF(COUNTIF($F$15:$F$102,$A14)+COUNTIF($G$15:$G$102,$A14)+COUNTIF($H$15:$H$102,$A14)=0,設定!$B$3,MIN(IF(COUNTIF($F$15:$F$102,$A14)=0,999999,IFERROR(WORKDAY(_xlfn.MINIFS($M$15:$M$102,$F$15:$F$102,$A14),-1),999999)),IF(COUNTIF($G$15:$G$102,$A14)=0,999999,IFERROR(WORKDAY(_xlfn.MINIFS($M$15:$M$102,$G$15:$G$102,$A14),-1),999999)),IF(COUNTIF($H$15:$H$102,$A14)=0,999999,IFERROR(WORKDAY(_xlfn.MINIFS($M$15:$M$102,$H$15:$H$102,$A14),-1),999999))))) | O14: =IF($A14="","",NETWORKDAYS($K14,$M14)-1) | P14: =IF($A14="","",IF($O14<=0,"クリティカル","")) | Q14: =IF($A14="","",IF(AND($J14<>"完了",TODAY()>$L14),"遅延","")) | R14: =IF($A14="","",_xlfn.TEXTJOIN(", ",TRUE(),IF($F14="","",IF(IFERROR(INDEX($J$3:$J$102,MATCH($F14,$A$3:$A$102,0)),"")<>"完了",IFERROR(INDEX($C$3:$C$102,MATCH($F14,$A$3:$A$102,0)),""),"")),IF($G14="","",IF(IFERROR(INDEX($J$3:$J$102,MATCH($G14,$A$3:$A$102,0)),"")<>"完了",IFERROR(INDEX($C$3:$C$102,MATCH($G14,$A$3:$A$102,0)),""),"")),IF($H14="","",IF(IFERROR(INDEX($J$3:$J$102,MATCH($H14,$A$3:$A$102,0)),"")<>"完了",IFERROR(INDEX($C$3:$C$102,MATCH($H14,$A$3:$A$102,0)),""),"")))) | S14: =IF($A14="","",IF($J14<>"完了",1,0))
K15: =IF($A15="","",IF(AND($F15="",$G15="",$H15=""),設定!$B$2,MAX(IF($F15="",0,IFERROR(WORKDAY(INDEX($L$3:$L$14,MATCH($F15,$A$3:$A$14,0)),1),0)),IF($G15="",0,IFERROR(WORKDAY(INDEX($L$3:$L$14,MATCH($G15,$A$3:$A$14,0)),1),0)),IF($H15="",0,IFERROR(WORKDAY(INDEX($L$3:$L$14,MATCH($H15,$A$3:$A$14,0)),1),0))))) | L15: =IF($A15="","",WORKDAY($K15,$I15-1)) | M15: =IF($A15="","",WORKDAY($N15,-($I15-1))) | N15: =IF($A15="","",IF(COUNTIF($F$16:$F$102,$A15)+COUNTIF($G$16:$G$102,$A15)+COUNTIF($H$16:$H$102,$A15)=0,設定!$B$3,MIN(IF(COUNTIF($F$16:$F$102,$A15)=0,999999,IFERROR(WORKDAY(_xlfn.MINIFS($M$16:$M$102,$F$16:$F$102,$A15),-1),999999)),IF(COUNTIF($G$16:$G$102,$A15)=0,999999,IFERROR(WORKDAY(_xlfn.MINIFS($M$16:$M$102,$G$16:$G$102,$A15),-1),999999)),IF(COUNTIF($H$16:$H$102,$A15)=0,999999,IFERROR(WORKDAY(_xlfn.MINIFS($M$16:$M$102,$H$16:$H$102,$A15),-1),999999))))) | O15: =IF($A15="","",NETWORKDAYS($K15,$M15)-1) | P15: =IF($A15="","",IF($O15<=0,"クリティカル","")) | Q15: =IF($A15="","",IF(AND($J15<>"完了",TODAY()>$L15),"遅延","")) | R15: =IF($A15="","",_xlfn.TEXTJOIN(", ",TRUE(),IF($F15="","",IF(IFERROR(INDEX($J$3:$J$102,MATCH($F15,$A$3:$A$102,0)),"")<>"完了",IFERROR(INDEX($C$3:$C$102,MATCH($F15,$A$3:$A$102,0)),""),"")),IF($G15="","",IF(IFERROR(INDEX($J$3:$J$102,MATCH($G15,$A$3:$A$102,0)),"")<>"完了",IFERROR(INDEX($C$3:$C$102,MATCH($G15,$A$3:$A$102,0)),""),"")),IF($H15="","",IF(IFERROR(INDEX($J$3:$J$102,MATCH($H15,$A$3:$A$102,0)),"")<>"完了",IFERROR(INDEX($C$3:$C$102,MATCH($H15,$A$3:$A$102,0)),""),"")))) | S15: =IF($A15="","",IF($J15<>"完了",1,0))
K16: =IF($A16="","",IF(AND($F16="",$G16="",$H16=""),設定!$B$2,MAX(IF($F16="",0,IFERROR(WORKDAY(INDEX($L$3:$L$15,MATCH($F16,$A$3:$A$15,0)),1),0)),IF($G16="",0,IFERROR(WORKDAY(INDEX($L$3:$L$15,MATCH($G16,$A$3:$A$15,0)),1),0)),IF($H16="",0,IFERROR(WORKDAY(INDEX($L$3:$L$15,MATCH($H16,$A$3:$A$15,0)),1),0))))) | L16: =IF($A16="","",WORKDAY($K16,$I16-1)) | M16: =IF($A16="","",WORKDAY($N16,-($I16-1))) | N16: =IF($A16="","",IF(COUNTIF($F$17:$F$102,$A16)+COUNTIF($G$17:$G$102,$A16)+COUNTIF($H$17:$H$102,$A16)=0,設定!$B$3,MIN(IF(COUNTIF($F$17:$F$102,$A16)=0,999999,IFERROR(WORKDAY(_xlfn.MINIFS($M$17:$M$102,$F$17:$F$102,$A16),-1),999999)),IF(COUNTIF($G$17:$G$102,$A16)=0,999999,IFERROR(WORKDAY(_xlfn.MINIFS($M$17:$M$102,$G$17:$G$102,$A16),-1),999999)),IF(COUNTIF($H$17:$H$102,$A16)=0,999999,IFERROR(WORKDAY(_xlfn.MINIFS($M$17:$M$102,$H$17:$H$102,$A16),-1),999999))))) | O16: =IF($A16="","",NETWORKDAYS($K16,$M16)-1) | P16: =IF($A16="","",IF($O16<=0,"クリティカル","")) | Q16: =IF($A16="","",IF(AND($J16<>"完了",TODAY()>$L16),"遅延","")) | R16: =IF($A16="","",_xlfn.TEXTJOIN(", ",TRUE(),IF($F16="","",IF(IFERROR(INDEX($J$3:$J$102,MATCH($F16,$A$3:$A$102,0)),"")<>"完了",IFERROR(INDEX($C$3:$C$102,MATCH($F16,$A$3:$A$102,0)),""),"")),IF($G16="","",IF(IFERROR(INDEX($J$3:$J$102,MATCH($G16,$A$3:$A$102,0)),"")<>"完了",IFERROR(INDEX($C$3:$C$102,MATCH($G16,$A$3:$A$102,0)),""),"")),IF($H16="","",IF(IFERROR(INDEX($J$3:$J$102,MATCH($H16,$A$3:$A$102,0)),"")<>"完了",IFERROR(INDEX($C$3:$C$102,MATCH($H16,$A$3:$A$102,0)),""),"")))) | S16: =IF($A16="","",IF($J16<>"完了",1,0))
K17: =IF($A17="","",IF(AND($F17="",$G17="",$H17=""),設定!$B$2,MAX(IF($F17="",0,IFERROR(WORKDAY(INDEX($L$3:$L$16,MATCH($F17,$A$3:$A$16,0)),1),0)),IF($G17="",0,IFERROR(WORKDAY(INDEX($L$3:$L$16,MATCH($G17,$A$3:$A$16,0)),1),0)),IF($H17="",0,IFERROR(WORKDAY(INDEX($L$3:$L$16,MATCH($H17,$A$3:$A$16,0)),1),0))))) | L17: =IF($A17="","",WORKDAY($K17,$I17-1)) | M17: =IF($A17="","",WORKDAY($N17,-($I17-1))) | N17: =IF($A17="","",IF(COUNTIF($F$18:$F$102,$A17)+COUNTIF($G$18:$G$102,$A17)+COUNTIF($H$18:$H$102,$A17)=0,設定!$B$3,MIN(IF(COUNTIF($F$18:$F$102,$A17)=0,999999,IFERROR(WORKDAY(_xlfn.MINIFS($M$18:$M$102,$F$18:$F$102,$A17),-1),999999)),IF(COUNTIF($G$18:$G$102,$A17)=0,999999,IFERROR(WORKDAY(_xlfn.MINIFS($M$18:$M$102,$G$18:$G$102,$A17),-1),999999)),IF(COUNTIF($H$18:$H$102,$A17)=0,999999,IFERROR(WORKDAY(_xlfn.MINIFS($M$18:$M$102,$H$18:$H$102,$A17),-1),999999))))) | O17: =IF($A17="","",NETWORKDAYS($K17,$M17)-1) | P17: =IF($A17="","",IF($O17<=0,"クリティカル","")) | Q17: =IF($A17="","",IF(AND($J17<>"完了",TODAY()>$L17),"遅延","")) | R17: =IF($A17="","",_xlfn.TEXTJOIN(", ",TRUE(),IF($F17="","",IF(IFERROR(INDEX($J$3:$J$102,MATCH($F17,$A$3:$A$102,0)),"")<>"完了",IFERROR(INDEX($C$3:$C$102,MATCH($F17,$A$3:$A$102,0)),""),"")),IF($G17="","",IF(IFERROR(INDEX($J$3:$J$102,MATCH($G17,$A$3:$A$102,0)),"")<>"完了",IFERROR(INDEX($C$3:$C$102,MATCH($G17,$A$3:$A$102,0)),""),"")),IF($H17="","",IF(IFERROR(INDEX($J$3:$J$102,MATCH($H17,$A$3:$A$102,0)),"")<>"完了",IFERROR(INDEX($C$3:$C$102,MATCH($H17,$A$3:$A$102,0)),""),"")))) | S17: =IF($A17="","",IF($J17<>"完了",1,0))
K18: =IF($A18="","",IF(AND($F18="",$G18="",$H18=""),設定!$B$2,MAX(IF($F18="",0,IFERROR(WORKDAY(INDEX($L$3:$L$17,MATCH($F18,$A$3:$A$17,0)),1),0)),IF($G18="",0,IFERROR(WORKDAY(INDEX($L$3:$L$17,MATCH($G18,$A$3:$A$17,0)),1),0)),IF($H18="",0,IFERROR(WORKDAY(INDEX($L$3:$L$17,MATCH($H18,$A$3:$A$17,0)),1),0))))) | L18: =IF($A18="","",WORKDAY($K18,$I18-1)) | M18: =IF($A18="","",WORKDAY($N18,-($I18-1))) | N18: =IF($A18="","",IF(COUNTIF($F$19:$F$102,$A18)+COUNTIF($G$19:$G$102,$A18)+COUNTIF($H$19:$H$102,$A18)=0,設定!$B$3,MIN(IF(COUNTIF($F$19:$F$102,$A18)=0,999999,IFERROR(WORKDAY(_xlfn.MINIFS($M$19:$M$102,$F$19:$F$102,$A18),-1),999999)),IF(COUNTIF($G$19:$G$102,$A18)=0,999999,IFERROR(WORKDAY(_xlfn.MINIFS($M$19:$M$102,$G$19:$G$102,$A18),-1),999999)),IF(COUNTIF($H$19:$H$102,$A18)=0,999999,IFERROR(WORKDAY(_xlfn.MINIFS($M$19:$M$102,$H$19:$H$102,$A18),-1),999999))))) | O18: =IF($A18="","",NETWORKDAYS($K18,$M18)-1) | P18: =IF($A18="","",IF($O18<=0,"クリティカル","")) | Q18: =IF($A18="","",IF(AND($J18<>"完了",TODAY()>$L18),"遅延","")) | R18: =IF($A18="","",_xlfn.TEXTJOIN(", ",TRUE(),IF($F18="","",IF(IFERROR(INDEX($J$3:$J$102,MATCH($F18,$A$3:$A$102,0)),"")<>"完了",IFERROR(INDEX($C$3:$C$102,MATCH($F18,$A$3:$A$102,0)),""),"")),IF($G18="","",IF(IFERROR(INDEX($J$3:$J$102,MATCH($G18,$A$3:$A$102,0)),"")<>"完了",IFERROR(INDEX($C$3:$C$102,MATCH($G18,$A$3:$A$102,0)),""),"")),IF($H18="","",IF(IFERROR(INDEX($J$3:$J$102,MATCH($H18,$A$3:$A$102,0)),"")<>"完了",IFERROR(INDEX($C$3:$C$102,MATCH($H18,$A$3:$A$102,0)),""),"")))) | S18: =IF($A18="","",IF($J18<>"完了",1,0))
K19: =IF($A19="","",IF(AND($F19="",$G19="",$H19=""),設定!$B$2,MAX(IF($F19="",0,IFERROR(WORKDAY(INDEX($L$3:$L$18,MATCH($F19,$A$3:$A$18,0)),1),0)),IF($G19="",0,IFERROR(WORKDAY(INDEX($L$3:$L$18,MATCH($G19,$A$3:$A$18,0)),1),0)),IF($H19="",0,IFERROR(WORKDAY(INDEX($L$3:$L$18,MATCH($H19,$A$3:$A$18,0)),1),0))))) | L19: =IF($A19="","",WORKDAY($K19,$I19-1)) | M19: =IF($A19="","",WORKDAY($N19,-($I19-1))) | N19: =IF($A19="","",IF(COUNTIF($F$20:$F$102,$A19)+COUNTIF($G$20:$G$102,$A19)+COUNTIF($H$20:$H$102,$A19)=0,設定!$B$3,MIN(IF(COUNTIF($F$20:$F$102,$A19)=0,999999,IFERROR(WORKDAY(_xlfn.MINIFS($M$20:$M$102,$F$20:$F$102,$A19),-1),999999)),IF(COUNTIF($G$20:$G$102,$A19)=0,999999,IFERROR(WORKDAY(_xlfn.MINIFS($M$20:$M$102,$G$20:$G$102,$A19),-1),999999)),IF(COUNTIF($H$20:$H$102,$A19)=0,999999,IFERROR(WORKDAY(_xlfn.MINIFS($M$20:$M$102,$H$20:$H$102,$A19),-1),999999))))) | O19: =IF($A19="","",NETWORKDAYS($K19,$M19)-1) | P19: =IF($A19="","",IF($O19<=0,"クリティカル","")) | Q19: =IF($A19="","",IF(AND($J19<>"完了",TODAY()>$L19),"遅延","")) | R19: =IF($A19="","",_xlfn.TEXTJOIN(", ",TRUE(),IF($F19="","",IF(IFERROR(INDEX($J$3:$J$102,MATCH($F19,$A$3:$A$102,0)),"")<>"完了",IFERROR(INDEX($C$3:$C$102,MATCH($F19,$A$3:$A$102,0)),""),"")),IF($G19="","",IF(IFERROR(INDEX($J$3:$J$102,MATCH($G19,$A$3:$A$102,0)),"")<>"完了",IFERROR(INDEX($C$3:$C$102,MATCH($G19,$A$3:$A$102,0)),""),"")),IF($H19="","",IF(IFERROR(INDEX($J$3:$J$102,MATCH($H19,$A$3:$A$102,0)),"")<>"完了",IFERROR(INDEX($C$3:$C$102,MATCH($H19,$A$3:$A$102,0)),""),"")))) | S19: =IF($A19="","",IF($J19<>"完了",1,0))
K20: =IF($A20="","",IF(AND($F20="",$G20="",$H20=""),設定!$B$2,MAX(IF($F20="",0,IFERROR(WORKDAY(INDEX($L$3:$L$19,MATCH($F20,$A$3:$A$19,0)),1),0)),IF($G20="",0,IFERROR(WORKDAY(INDEX($L$3:$L$19,MATCH($G20,$A$3:$A$19,0)),1),0)),IF($H20="",0,IFERROR(WORKDAY(INDEX($L$3:$L$19,MATCH($H20,$A$3:$A$19,0)),1),0))))) | L20: =IF($A20="","",WORKDAY($K20,$I20-1)) | M20: =IF($A20="","",WORKDAY($N20,-($I20-1))) | N20: =IF($A20="","",IF(COUNTIF($F$21:$F$102,$A20)+COUNTIF($G$21:$G$102,$A20)+COUNTIF($H$21:$H$102,$A20)=0,設定!$B$3,MIN(IF(COUNTIF($F$21:$F$102,$A20)=0,999999,IFERROR(WORKDAY(_xlfn.MINIFS($M$21:$M$102,$F$21:$F$102,$A20),-1),999999)),IF(COUNTIF($G$21:$G$102,$A20)=0,999999,IFERROR(WORKDAY(_xlfn.MINIFS($M$21:$M$102,$G$21:$G$102,$A20),-1),999999)),IF(COUNTIF($H$21:$H$102,$A20)=0,999999,IFERROR(WORKDAY(_xlfn.MINIFS($M$21:$M$102,$H$21:$H$102,$A20),-1),999999))))) | O20: =IF($A20="","",NETWORKDAYS($K20,$M20)-1) | P20: =IF($A20="","",IF($O20<=0,"クリティカル","")) | Q20: =IF($A20="","",IF(AND($J20<>"完了",TODAY()>$L20),"遅延","")) | R20: =IF($A20="","",_xlfn.TEXTJOIN(", ",TRUE(),IF($F20="","",IF(IFERROR(INDEX($J$3:$J$102,MATCH($F20,$A$3:$A$102,0)),"")<>"完了",IFERROR(INDEX($C$3:$C$102,MATCH($F20,$A$3:$A$102,0)),""),"")),IF($G20="","",IF(IFERROR(INDEX($J$3:$J$102,MATCH($G20,$A$3:$A$102,0)),"")<>"完了",IFERROR(INDEX($C$3:$C$102,MATCH($G20,$A$3:$A$102,0)),""),"")),IF($H20="","",IF(IFERROR(INDEX($J$3:$J$102,MATCH($H20,$A$3:$A$102,0)),"")<>"完了",IFERROR(INDEX($C$3:$C$102,MATCH($H20,$A$3:$A$102,0)),""),"")))) | S20: =IF($A20="","",IF($J20<>"完了",1,0))
K21: =IF($A21="","",IF(AND($F21="",$G21="",$H21=""),設定!$B$2,MAX(IF($F21="",0,IFERROR(WORKDAY(INDEX($L$3:$L$20,MATCH($F21,$A$3:$A$20,0)),1),0)),IF($G21="",0,IFERROR(WORKDAY(INDEX($L$3:$L$20,MATCH($G21,$A$3:$A$20,0)),1),0)),IF($H21="",0,IFERROR(WORKDAY(INDEX($L$3:$L$20,MATCH($H21,$A$3:$A$20,0)),1),0))))) | L21: =IF($A21="","",WORKDAY($K21,$I21-1)) | M21: =IF($A21="","",WORKDAY($N21,-($I21-1))) | N21: =IF($A21="","",IF(COUNTIF($F$22:$F$102,$A21)+COUNTIF($G$22:$G$102,$A21)+COUNTIF($H$22:$H$102,$A21)=0,設定!$B$3,MIN(IF(COUNTIF($F$22:$F$102,$A21)=0,999999,IFERROR(WORKDAY(_xlfn.MINIFS($M$22:$M$102,$F$22:$F$102,$A21),-1),999999)),IF(COUNTIF($G$22:$G$102,$A21)=0,999999,IFERROR(WORKDAY(_xlfn.MINIFS($M$22:$M$102,$G$22:$G$102,$A21),-1),999999)),IF(COUNTIF($H$22:$H$102,$A21)=0,999999,IFERROR(WORKDAY(_xlfn.MINIFS($M$22:$M$102,$H$22:$H$102,$A21),-1),999999))))) | O21: =IF($A21="","",NETWORKDAYS($K21,$M21)-1) | P21: =IF($A21="","",IF($O21<=0,"クリティカル","")) | Q21: =IF($A21="","",IF(AND($J21<>"完了",TODAY()>$L21),"遅延","")) | R21: =IF($A21="","",_xlfn.TEXTJOIN(", ",TRUE(),IF($F21="","",IF(IFERROR(INDEX($J$3:$J$102,MATCH($F21,$A$3:$A$102,0)),"")<>"完了",IFERROR(INDEX($C$3:$C$102,MATCH($F21,$A$3:$A$102,0)),""),"")),IF($G21="","",IF(IFERROR(INDEX($J$3:$J$102,MATCH($G21,$A$3:$A$102,0)),"")<>"完了",IFERROR(INDEX($C$3:$C$102,MATCH($G21,$A$3:$A$102,0)),""),"")),IF($H21="","",IF(IFERROR(INDEX($J$3:$J$102,MATCH($H21,$A$3:$A$102,0)),"")<>"完了",IFERROR(INDEX($C$3:$C$102,MATCH($H21,$A$3:$A$102,0)),""),"")))) | S21: =IF($A21="","",IF($J21<>"完了",1,0))
K22: =IF($A22="","",IF(AND($F22="",$G22="",$H22=""),設定!$B$2,MAX(IF($F22="",0,IFERROR(WORKDAY(INDEX($L$3:$L$21,MATCH($F22,$A$3:$A$21,0)),1),0)),IF($G22="",0,IFERROR(WORKDAY(INDEX($L$3:$L$21,MATCH($G22,$A$3:$A$21,0)),1),0)),IF($H22="",0,IFERROR(WORKDAY(INDEX($L$3:$L$21,MATCH($H22,$A$3:$A$21,0)),1),0))))) | L22: =IF($A22="","",WORKDAY($K22,$I22-1)) | M22: =IF($A22="","",WORKDAY($N22,-($I22-1))) | N22: =IF($A22="","",IF(COUNTIF($F$23:$F$102,$A22)+COUNTIF($G$23:$G$102,$A22)+COUNTIF($H$23:$H$102,$A22)=0,設定!$B$3,MIN(IF(COUNTIF($F$23:$F$102,$A22)=0,999999,IFERROR(WORKDAY(_xlfn.MINIFS($M$23:$M$102,$F$23:$F$102,$A22),-1),999999)),IF(COUNTIF($G$23:$G$102,$A22)=0,999999,IFERROR(WORKDAY(_xlfn.MINIFS($M$23:$M$102,$G$23:$G$102,$A22),-1),999999)),IF(COUNTIF($H$23:$H$102,$A22)=0,999999,IFERROR(WORKDAY(_xlfn.MINIFS($M$23:$M$102,$H$23:$H$102,$A22),-1),999999))))) | O22: =IF($A22="","",NETWORKDAYS($K22,$M22)-1) | P22: =IF($A22="","",IF($O22<=0,"クリティカル","")) | Q22: =IF($A22="","",IF(AND($J22<>"完了",TODAY()>$L22),"遅延","")) | R22: =IF($A22="","",_xlfn.TEXTJOIN(", ",TRUE(),IF($F22="","",IF(IFERROR(INDEX($J$3:$J$102,MATCH($F22,$A$3:$A$102,0)),"")<>"完了",IFERROR(INDEX($C$3:$C$102,MATCH($F22,$A$3:$A$102,0)),""),"")),IF($G22="","",IF(IFERROR(INDEX($J$3:$J$102,MATCH($G22,$A$3:$A$102,0)),"")<>"完了",IFERROR(INDEX($C$3:$C$102,MATCH($G22,$A$3:$A$102,0)),""),"")),IF($H22="","",IF(IFERROR(INDEX($J$3:$J$102,MATCH($H22,$A$3:$A$102,0)),"")<>"完了",IFERROR(INDEX($C$3:$C$102,MATCH($H22,$A$3:$A$102,0)),""),"")))) | S22: =IF($A22="","",IF($J22<>"完了",1,0))
K23: =IF($A23="","",IF(AND($F23="",$G23="",$H23=""),設定!$B$2,MAX(IF($F23="",0,IFERROR(WORKDAY(INDEX($L$3:$L$22,MATCH($F23,$A$3:$A$22,0)),1),0)),IF($G23="",0,IFERROR(WORKDAY(INDEX($L$3:$L$22,MATCH($G23,$A$3:$A$22,0)),1),0)),IF($H23="",0,IFERROR(WORKDAY(INDEX($L$3:$L$22,MATCH($H23,$A$3:$A$22,0)),1),0))))) | L23: =IF($A23="","",WORKDAY($K23,$I23-1)) | M23: =IF($A23="","",WORKDAY($N23,-($I23-1))) | N23: =IF($A23="","",IF(COUNTIF($F$24:$F$102,$A23)+COUNTIF($G$24:$G$102,$A23)+COUNTIF($H$24:$H$102,$A23)=0,設定!$B$3,MIN(IF(COUNTIF($F$24:$F$102,$A23)=0,999999,IFERROR(WORKDAY(_xlfn.MINIFS($M$24:$M$102,$F$24:$F$102,$A23),-1),999999)),IF(COUNTIF($G$24:$G$102,$A23)=0,999999,IFERROR(WORKDAY(_xlfn.MINIFS($M$24:$M$102,$G$24:$G$102,$A23),-1),999999)),IF(COUNTIF($H$24:$H$102,$A23)=0,999999,IFERROR(WORKDAY(_xlfn.MINIFS($M$24:$M$102,$H$24:$H$102,$A23),-1),999999))))) | O23: =IF($A23="","",NETWORKDAYS($K23,$M23)-1) | P23: =IF($A23="","",IF($O23<=0,"クリティカル","")) | Q23: =IF($A23="","",IF(AND($J23<>"完了",TODAY()>$L23),"遅延","")) | R23: =IF($A23="","",_xlfn.TEXTJOIN(", ",TRUE(),IF($F23="","",IF(IFERROR(INDEX($J$3:$J$102,MATCH($F23,$A$3:$A$102,0)),"")<>"完了",IFERROR(INDEX($C$3:$C$102,MATCH($F23,$A$3:$A$102,0)),""),"")),IF($G23="","",IF(IFERROR(INDEX($J$3:$J$102,MATCH($G23,$A$3:$A$102,0)),"")<>"完了",IFERROR(INDEX($C$3:$C$102,MATCH($G23,$A$3:$A$102,0)),""),"")),IF($H23="","",IF(IFERROR(INDEX($J$3:$J$102,MATCH($H23,$A$3:$A$102,0)),"")<>"完了",IFERROR(INDEX($C$3:$C$102,MATCH($H23,$A$3:$A$102,0)),""),"")))) | S23: =IF($A23="","",IF($J23<>"完了",1,0))
K24: =IF($A24="","",IF(AND($F24="",$G24="",$H24=""),設定!$B$2,MAX(IF($F24="",0,IFERROR(WORKDAY(INDEX($L$3:$L$23,MATCH($F24,$A$3:$A$23,0)),1),0)),IF($G24="",0,IFERROR(WORKDAY(INDEX($L$3:$L$23,MATCH($G24,$A$3:$A$23,0)),1),0)),IF($H24="",0,IFERROR(WORKDAY(INDEX($L$3:$L$23,MATCH($H24,$A$3:$A$23,0)),1),0))))) | L24: =IF($A24="","",WORKDAY($K24,$I24-1)) | M24: =IF($A24="","",WORKDAY($N24,-($I24-1))) | N24: =IF($A24="","",IF(COUNTIF($F$25:$F$102,$A24)+COUNTIF($G$25:$G$102,$A24)+COUNTIF($H$25:$H$102,$A24)=0,設定!$B$3,MIN(IF(COUNTIF($F$25:$F$102,$A24)=0,999999,IFERROR(WORKDAY(_xlfn.MINIFS($M$25:$M$102,$F$25:$F$102,$A24),-1),999999)),IF(COUNTIF($G$25:$G$102,$A24)=0,999999,IFERROR(WORKDAY(_xlfn.MINIFS($M$25:$M$102,$G$25:$G$102,$A24),-1),999999)),IF(COUNTIF($H$25:$H$102,$A24)=0,999999,IFERROR(WORKDAY(_xlfn.MINIFS($M$25:$M$102,$H$25:$H$102,$A24),-1),999999))))) | O24: =IF($A24="","",NETWORKDAYS($K24,$M24)-1) | P24: =IF($A24="","",IF($O24<=0,"クリティカル","")) | Q24: =IF($A24="","",IF(AND($J24<>"完了",TODAY()>$L24),"遅延","")) | R24: =IF($A24="","",_xlfn.TEXTJOIN(", ",TRUE(),IF($F24="","",IF(IFERROR(INDEX($J$3:$J$102,MATCH($F24,$A$3:$A$102,0)),"")<>"完了",IFERROR(INDEX($C$3:$C$102,MATCH($F24,$A$3:$A$102,0)),""),"")),IF($G24="","",IF(IFERROR(INDEX($J$3:$J$102,MATCH($G24,$A$3:$A$102,0)),"")<>"完了",IFERROR(INDEX($C$3:$C$102,MATCH($G24,$A$3:$A$102,0)),""),"")),IF($H24="","",IF(IFERROR(INDEX($J$3:$J$102,MATCH($H24,$A$3:$A$102,0)),"")<>"完了",IFERROR(INDEX($C$3:$C$102,MATCH($H24,$A$3:$A$102,0)),""),"")))) | S24: =IF($A24="","",IF($J24<>"完了",1,0))
K25: =IF($A25="","",IF(AND($F25="",$G25="",$H25=""),設定!$B$2,MAX(IF($F25="",0,IFERROR(WORKDAY(INDEX($L$3:$L$24,MATCH($F25,$A$3:$A$24,0)),1),0)),IF($G25="",0,IFERROR(WORKDAY(INDEX($L$3:$L$24,MATCH($G25,$A$3:$A$24,0)),1),0)),IF($H25="",0,IFERROR(WORKDAY(INDEX($L$3:$L$24,MATCH($H25,$A$3:$A$24,0)),1),0))))) | L25: =IF($A25="","",WORKDAY($K25,$I25-1)) | M25: =IF($A25="","",WORKDAY($N25,-($I25-1))) | N25: =IF($A25="","",IF(COUNTIF($F$26:$F$102,$A25)+COUNTIF($G$26:$G$102,$A25)+COUNTIF($H$26:$H$102,$A25)=0,設定!$B$3,MIN(IF(COUNTIF($F$26:$F$102,$A25)=0,999999,IFERROR(WORKDAY(_xlfn.MINIFS($M$26:$M$102,$F$26:$F$102,$A25),-1),999999)),IF(COUNTIF($G$26:$G$102,$A25)=0,999999,IFERROR(WORKDAY(_xlfn.MINIFS($M$26:$M$102,$G$26:$G$102,$A25),-1),999999)),IF(COUNTIF($H$26:$H$102,$A25)=0,999999,IFERROR(WORKDAY(_xlfn.MINIFS($M$26:$M$102,$H$26:$H$102,$A25),-1),999999))))) | O25: =IF($A25="","",NETWORKDAYS($K25,$M25)-1) | P25: =IF($A25="","",IF($O25<=0,"クリティカル","")) | Q25: =IF($A25="","",IF(AND($J25<>"完了",TODAY()>$L25),"遅延","")) | R25: =IF($A25="","",_xlfn.TEXTJOIN(", ",TRUE(),IF($F25="","",IF(IFERROR(INDEX($J$3:$J$102,MATCH($F25,$A$3:$A$102,0)),"")<>"完了",IFERROR(INDEX($C$3:$C$102,MATCH($F25,$A$3:$A$102,0)),""),"")),IF($G25="","",IF(IFERROR(INDEX($J$3:$J$102,MATCH($G25,$A$3:$A$102,0)),"")<>"完了",IFERROR(INDEX($C$3:$C$102,MATCH($G25,$A$3:$A$102,0)),""),"")),IF($H25="","",IF(IFERROR(INDEX($J$3:$J$102,MATCH($H25,$A$3:$A$102,0)),"")<>"完了",IFERROR(INDEX($C$3:$C$102,MATCH($H25,$A$3:$A$102,0)),""),"")))) | S25: =IF($A25="","",IF($J25<>"完了",1,0))
K26: =IF($A26="","",IF(AND($F26="",$G26="",$H26=""),設定!$B$2,MAX(IF($F26="",0,IFERROR(WORKDAY(INDEX($L$3:$L$25,MATCH($F26,$A$3:$A$25,0)),1),0)),IF($G26="",0,IFERROR(WORKDAY(INDEX($L$3:$L$25,MATCH($G26,$A$3:$A$25,0)),1),0)),IF($H26="",0,IFERROR(WORKDAY(INDEX($L$3:$L$25,MATCH($H26,$A$3:$A$25,0)),1),0))))) | L26: =IF($A26="","",WORKDAY($K26,$I26-1)) | M26: =IF($A26="","",WORKDAY($N26,-($I26-1))) | N26: =IF($A26="","",IF(COUNTIF($F$27:$F$102,$A26)+COUNTIF($G$27:$G$102,$A26)+COUNTIF($H$27:$H$102,$A26)=0,設定!$B$3,MIN(IF(COUNTIF($F$27:$F$102,$A26)=0,999999,IFERROR(WORKDAY(_xlfn.MINIFS($M$27:$M$102,$F$27:$F$102,$A26),-1),999999)),IF(COUNTIF($G$27:$G$102,$A26)=0,999999,IFERROR(WORKDAY(_xlfn.MINIFS($M$27:$M$102,$G$27:$G$102,$A26),-1),999999)),IF(COUNTIF($H$27:$H$102,$A26)=0,999999,IFERROR(WORKDAY(_xlfn.MINIFS($M$27:$M$102,$H$27:$H$102,$A26),-1),999999))))) | O26: =IF($A26="","",NETWORKDAYS($K26,$M26)-1) | P26: =IF($A26="","",IF($O26<=0,"クリティカル","")) | Q26: =IF($A26="","",IF(AND($J26<>"完了",TODAY()>$L26),"遅延","")) | R26: =IF($A26="","",_xlfn.TEXTJOIN(", ",TRUE(),IF($F26="","",IF(IFERROR(INDEX($J$3:$J$102,MATCH($F26,$A$3:$A$102,0)),"")<>"完了",IFERROR(INDEX($C$3:$C$102,MATCH($F26,$A$3:$A$102,0)),""),"")),IF($G26="","",IF(IFERROR(INDEX($J$3:$J$102,MATCH($G26,$A$3:$A$102,0)),"")<>"完了",IFERROR(INDEX($C$3:$C$102,MATCH($G26,$A$3:$A$102,0)),""),"")),IF($H26="","",IF(IFERROR(INDEX($J$3:$J$102,MATCH($H26,$A$3:$A$102,0)),"")<>"完了",IFERROR(INDEX($C$3:$C$102,MATCH($H26,$A$3:$A$102,0)),""),"")))) | S26: =IF($A26="","",IF($J26<>"完了",1,0))
K27: =IF($A27="","",IF(AND($F27="",$G27="",$H27=""),設定!$B$2,MAX(IF($F27="",0,IFERROR(WORKDAY(INDEX($L$3:$L$26,MATCH($F27,$A$3:$A$26,0)),1),0)),IF($G27="",0,IFERROR(WORKDAY(INDEX($L$3:$L$26,MATCH($G27,$A$3:$A$26,0)),1),0)),IF($H27="",0,IFERROR(WORKDAY(INDEX($L$3:$L$26,MATCH($H27,$A$3:$A$26,0)),1),0))))) | L27: =IF($A27="","",WORKDAY($K27,$I27-1)) | M27: =IF($A27="","",WORKDAY($N27,-($I27-1))) | N27: =IF($A27="","",IF(COUNTIF($F$28:$F$102,$A27)+COUNTIF($G$28:$G$102,$A27)+COUNTIF($H$28:$H$102,$A27)=0,設定!$B$3,MIN(IF(COUNTIF($F$28:$F$102,$A27)=0,999999,IFERROR(WORKDAY(_xlfn.MINIFS($M$28:$M$102,$F$28:$F$102,$A27),-1),999999)),IF(COUNTIF($G$28:$G$102,$A27)=0,999999,IFERROR(WORKDAY(_xlfn.MINIFS($M$28:$M$102,$G$28:$G$102,$A27),-1),999999)),IF(COUNTIF($H$28:$H$102,$A27)=0,999999,IFERROR(WORKDAY(_xlfn.MINIFS($M$28:$M$102,$H$28:$H$102,$A27),-1),999999))))) | O27: =IF($A27="","",NETWORKDAYS($K27,$M27)-1) | P27: =IF($A27="","",IF($O27<=0,"クリティカル","")) | Q27: =IF($A27="","",IF(AND($J27<>"完了",TODAY()>$L27),"遅延","")) | R27: =IF($A27="","",_xlfn.TEXTJOIN(", ",TRUE(),IF($F27="","",IF(IFERROR(INDEX($J$3:$J$102,MATCH($F27,$A$3:$A$102,0)),"")<>"完了",IFERROR(INDEX($C$3:$C$102,MATCH($F27,$A$3:$A$102,0)),""),"")),IF($G27="","",IF(IFERROR(INDEX($J$3:$J$102,MATCH($G27,$A$3:$A$102,0)),"")<>"完了",IFERROR(INDEX($C$3:$C$102,MATCH($G27,$A$3:$A$102,0)),""),"")),IF($H27="","",IF(IFERROR(INDEX($J$3:$J$102,MATCH($H27,$A$3:$A$102,0)),"")<>"完了",IFERROR(INDEX($C$3:$C$102,MATCH($H27,$A$3:$A$102,0)),""),"")))) | S27: =IF($A27="","",IF($J27<>"完了",1,0))
K28: =IF($A28="","",IF(AND($F28="",$G28="",$H28=""),設定!$B$2,MAX(IF($F28="",0,IFERROR(WORKDAY(INDEX($L$3:$L$27,MATCH($F28,$A$3:$A$27,0)),1),0)),IF($G28="",0,IFERROR(WORKDAY(INDEX($L$3:$L$27,MATCH($G28,$A$3:$A$27,0)),1),0)),IF($H28="",0,IFERROR(WORKDAY(INDEX($L$3:$L$27,MATCH($H28,$A$3:$A$27,0)),1),0))))) | L28: =IF($A28="","",WORKDAY($K28,$I28-1)) | M28: =IF($A28="","",WORKDAY($N28,-($I28-1))) | N28: =IF($A28="","",IF(COUNTIF($F$29:$F$102,$A28)+COUNTIF($G$29:$G$102,$A28)+COUNTIF($H$29:$H$102,$A28)=0,設定!$B$3,MIN(IF(COUNTIF($F$29:$F$102,$A28)=0,999999,IFERROR(WORKDAY(_xlfn.MINIFS($M$29:$M$102,$F$29:$F$102,$A28),-1),999999)),IF(COUNTIF($G$29:$G$102,$A28)=0,999999,IFERROR(WORKDAY(_xlfn.MINIFS($M$29:$M$102,$G$29:$G$102,$A28),-1),999999)),IF(COUNTIF($H$29:$H$102,$A28)=0,999999,IFERROR(WORKDAY(_xlfn.MINIFS($M$29:$M$102,$H$29:$H$102,$A28),-1),999999))))) | O28: =IF($A28="","",NETWORKDAYS($K28,$M28)-1) | P28: =IF($A28="","",IF($O28<=0,"クリティカル","")) | Q28: =IF($A28="","",IF(AND($J28<>"完了",TODAY()>$L28),"遅延","")) | R28: =IF($A28="","",_xlfn.TEXTJOIN(", ",TRUE(),IF($F28="","",IF(IFERROR(INDEX($J$3:$J$102,MATCH($F28,$A$3:$A$102,0)),"")<>"完了",IFERROR(INDEX($C$3:$C$102,MATCH($F28,$A$3:$A$102,0)),""),"")),IF($G28="","",IF(IFERROR(INDEX($J$3:$J$102,MATCH($G28,$A$3:$A$102,0)),"")<>"完了",IFERROR(INDEX($C$3:$C$102,MATCH($G28,$A$3:$A$102,0)),""),"")),IF($H28="","",IF(IFERROR(INDEX($J$3:$J$102,MATCH($H28,$A$3:$A$102,0)),"")<>"完了",IFERROR(INDEX($C$3:$C$102,MATCH($H28,$A$3:$A$102,0)),""),"")))) | S28: =IF($A28="","",IF($J28<>"完了",1,0))
K29: =IF($A29="","",IF(AND($F29="",$G29="",$H29=""),設定!$B$2,MAX(IF($F29="",0,IFERROR(WORKDAY(INDEX($L$3:$L$28,MATCH($F29,$A$3:$A$28,0)),1),0)),IF($G29="",0,IFERROR(WORKDAY(INDEX($L$3:$L$28,MATCH($G29,$A$3:$A$28,0)),1),0)),IF($H29="",0,IFERROR(WORKDAY(INDEX($L$3:$L$28,MATCH($H29,$A$3:$A$28,0)),1),0))))) | L29: =IF($A29="","",WORKDAY($K29,$I29-1)) | M29: =IF($A29="","",WORKDAY($N29,-($I29-1))) | N29: =IF($A29="","",IF(COUNTIF($F$30:$F$102,$A29)+COUNTIF($G$30:$G$102,$A29)+COUNTIF($H$30:$H$102,$A29)=0,設定!$B$3,MIN(IF(COUNTIF($F$30:$F$102,$A29)=0,999999,IFERROR(WORKDAY(_xlfn.MINIFS($M$30:$M$102,$F$30:$F$102,$A29),-1),999999)),IF(COUNTIF($G$30:$G$102,$A29)=0,999999,IFERROR(WORKDAY(_xlfn.MINIFS($M$30:$M$102,$G$30:$G$102,$A29),-1),999999)),IF(COUNTIF($H$30:$H$102,$A29)=0,999999,IFERROR(WORKDAY(_xlfn.MINIFS($M$30:$M$102,$H$30:$H$102,$A29),-1),999999))))) | O29: =IF($A29="","",NETWORKDAYS($K29,$M29)-1) | P29: =IF($A29="","",IF($O29<=0,"クリティカル","")) | Q29: =IF($A29="","",IF(AND($J29<>"完了",TODAY()>$L29),"遅延","")) | R29: =IF($A29="","",_xlfn.TEXTJOIN(", ",TRUE(),IF($F29="","",IF(IFERROR(INDEX($J$3:$J$102,MATCH($F29,$A$3:$A$102,0)),"")<>"完了",IFERROR(INDEX($C$3:$C$102,MATCH($F29,$A$3:$A$102,0)),""),"")),IF($G29="","",IF(IFERROR(INDEX($J$3:$J$102,MATCH($G29,$A$3:$A$102,0)),"")<>"完了",IFERROR(INDEX($C$3:$C$102,MATCH($G29,$A$3:$A$102,0)),""),"")),IF($H29="","",IF(IFERROR(INDEX($J$3:$J$102,MATCH($H29,$A$3:$A$102,0)),"")<>"完了",IFERROR(INDEX($C$3:$C$102,MATCH($H29,$A$3:$A$102,0)),""),"")))) | S29: =IF($A29="","",IF($J29<>"完了",1,0))
K30: =IF($A30="","",IF(AND($F30="",$G30="",$H30=""),設定!$B$2,MAX(IF($F30="",0,IFERROR(WORKDAY(INDEX($L$3:$L$29,MATCH($F30,$A$3:$A$29,0)),1),0)),IF($G30="",0,IFERROR(WORKDAY(INDEX($L$3:$L$29,MATCH($G30,$A$3:$A$29,0)),1),0)),IF($H30="",0,IFERROR(WORKDAY(INDEX($L$3:$L$29,MATCH($H30,$A$3:$A$29,0)),1),0))))) | L30: =IF($A30="","",WORKDAY($K30,$I30-1)) | M30: =IF($A30="","",WORKDAY($N30,-($I30-1))) | N30: =IF($A30="","",IF(COUNTIF($F$31:$F$102,$A30)+COUNTIF($G$31:$G$102,$A30)+COUNTIF($H$31:$H$102,$A30)=0,設定!$B$3,MIN(IF(COUNTIF($F$31:$F$102,$A30)=0,999999,IFERROR(WORKDAY(_xlfn.MINIFS($M$31:$M$102,$F$31:$F$102,$A30),-1),999999)),IF(COUNTIF($G$31:$G$102,$A30)=0,999999,IFERROR(WORKDAY(_xlfn.MINIFS($M$31:$M$102,$G$31:$G$102,$A30),-1),999999)),IF(COUNTIF($H$31:$H$102,$A30)=0,999999,IFERROR(WORKDAY(_xlfn.MINIFS($M$31:$M$102,$H$31:$H$102,$A30),-1),999999))))) | O30: =IF($A30="","",NETWORKDAYS($K30,$M30)-1) | P30: =IF($A30="","",IF($O30<=0,"クリティカル","")) | Q30: =IF($A30="","",IF(AND($J30<>"完了",TODAY()>$L30),"遅延","")) | R30: =IF($A30="","",_xlfn.TEXTJOIN(", ",TRUE(),IF($F30="","",IF(IFERROR(INDEX($J$3:$J$102,MATCH($F30,$A$3:$A$102,0)),"")<>"完了",IFERROR(INDEX($C$3:$C$102,MATCH($F30,$A$3:$A$102,0)),""),"")),IF($G30="","",IF(IFERROR(INDEX($J$3:$J$102,MATCH($G30,$A$3:$A$102,0)),"")<>"完了",IFERROR(INDEX($C$3:$C$102,MATCH($G30,$A$3:$A$102,0)),""),"")),IF($H30="","",IF(IFERROR(INDEX($J$3:$J$102,MATCH($H30,$A$3:$A$102,0)),"")<>"完了",IFERROR(INDEX($C$3:$C$102,MATCH($H30,$A$3:$A$102,0)),""),"")))) | S30: =IF($A30="","",IF($J30<>"完了",1,0))
K31: =IF($A31="","",IF(AND($F31="",$G31="",$H31=""),設定!$B$2,MAX(IF($F31="",0,IFERROR(WORKDAY(INDEX($L$3:$L$30,MATCH($F31,$A$3:$A$30,0)),1),0)),IF($G31="",0,IFERROR(WORKDAY(INDEX($L$3:$L$30,MATCH($G31,$A$3:$A$30,0)),1),0)),IF($H31="",0,IFERROR(WORKDAY(INDEX($L$3:$L$30,MATCH($H31,$A$3:$A$30,0)),1),0))))) | L31: =IF($A31="","",WORKDAY($K31,$I31-1)) | M31: =IF($A31="","",WORKDAY($N31,-($I31-1))) | N31: =IF($A31="","",IF(COUNTIF($F$32:$F$102,$A31)+COUNTIF($G$32:$G$102,$A31)+COUNTIF($H$32:$H$102,$A31)=0,設定!$B$3,MIN(IF(COUNTIF($F$32:$F$102,$A31)=0,999999,IFERROR(WORKDAY(_xlfn.MINIFS($M$32:$M$102,$F$32:$F$102,$A31),-1),999999)),IF(COUNTIF($G$32:$G$102,$A31)=0,999999,IFERROR(WORKDAY(_xlfn.MINIFS($M$32:$M$102,$G$32:$G$102,$A31),-1),999999)),IF(COUNTIF($H$32:$H$102,$A31)=0,999999,IFERROR(WORKDAY(_xlfn.MINIFS($M$32:$M$102,$H$32:$H$102,$A31),-1),999999))))) | O31: =IF($A31="","",NETWORKDAYS($K31,$M31)-1) | P31: =IF($A31="","",IF($O31<=0,"クリティカル","")) | Q31: =IF($A31="","",IF(AND($J31<>"完了",TODAY()>$L31),"遅延","")) | R31: =IF($A31="","",_xlfn.TEXTJOIN(", ",TRUE(),IF($F31="","",IF(IFERROR(INDEX($J$3:$J$102,MATCH($F31,$A$3:$A$102,0)),"")<>"完了",IFERROR(INDEX($C$3:$C$102,MATCH($F31,$A$3:$A$102,0)),""),"")),IF($G31="","",IF(IFERROR(INDEX($J$3:$J$102,MATCH($G31,$A$3:$A$102,0)),"")<>"完了",IFERROR(INDEX($C$3:$C$102,MATCH($G31,$A$3:$A$102,0)),""),"")),IF($H31="","",IF(IFERROR(INDEX($J$3:$J$102,MATCH($H31,$A$3:$A$102,0)),"")<>"完了",IFERROR(INDEX($C$3:$C$102,MATCH($H31,$A$3:$A$102,0)),""),"")))) | S31: =IF($A31="","",IF($J31<>"完了",1,0))
K32: =IF($A32="","",IF(AND($F32="",$G32="",$H32=""),設定!$B$2,MAX(IF($F32="",0,IFERROR(WORKDAY(INDEX($L$3:$L$31,MATCH($F32,$A$3:$A$31,0)),1),0)),IF($G32="",0,IFERROR(WORKDAY(INDEX($L$3:$L$31,MATCH($G32,$A$3:$A$31,0)),1),0)),IF($H32="",0,IFERROR(WORKDAY(INDEX($L$3:$L$31,MATCH($H32,$A$3:$A$31,0)),1),0))))) | L32: =IF($A32="","",WORKDAY($K32,$I32-1)) | M32: =IF($A32="","",WORKDAY($N32,-($I32-1))) | N32: =IF($A32="","",IF(COUNTIF($F$33:$F$102,$A32)+COUNTIF($G$33:$G$102,$A32)+COUNTIF($H$33:$H$102,$A32)=0,設定!$B$3,MIN(IF(COUNTIF($F$33:$F$102,$A32)=0,999999,IFERROR(WORKDAY(_xlfn.MINIFS($M$33:$M$102,$F$33:$F$102,$A32),-1),999999)),IF(COUNTIF($G$33:$G$102,$A32)=0,999999,IFERROR(WORKDAY(_xlfn.MINIFS($M$33:$M$102,$G$33:$G$102,$A32),-1),999999)),IF(COUNTIF($H$33:$H$102,$A32)=0,999999,IFERROR(WORKDAY(_xlfn.MINIFS($M$33:$M$102,$H$33:$H$102,$A32),-1),999999))))) | O32: =IF($A32="","",NETWORKDAYS($K32,$M32)-1) | P32: =IF($A32="","",IF($O32<=0,"クリティカル","")) | Q32: =IF($A32="","",IF(AND($J32<>"完了",TODAY()>$L32),"遅延","")) | R32: =IF($A32="","",_xlfn.TEXTJOIN(", ",TRUE(),IF($F32="","",IF(IFERROR(INDEX($J$3:$J$102,MATCH($F32,$A$3:$A$102,0)),"")<>"完了",IFERROR(INDEX($C$3:$C$102,MATCH($F32,$A$3:$A$102,0)),""),"")),IF($G32="","",IF(IFERROR(INDEX($J$3:$J$102,MATCH($G32,$A$3:$A$102,0)),"")<>"完了",IFERROR(INDEX($C$3:$C$102,MATCH($G32,$A$3:$A$102,0)),""),"")),IF($H32="","",IF(IFERROR(INDEX($J$3:$J$102,MATCH($H32,$A$3:$A$102,0)),"")<>"完了",IFERROR(INDEX($C$3:$C$102,MATCH($H32,$A$3:$A$102,0)),""),"")))) | S32: =IF($A32="","",IF($J32<>"完了",1,0))
K33: =IF($A33="","",IF(AND($F33="",$G33="",$H33=""),設定!$B$2,MAX(IF($F33="",0,IFERROR(WORKDAY(INDEX($L$3:$L$32,MATCH($F33,$A$3:$A$32,0)),1),0)),IF($G33="",0,IFERROR(WORKDAY(INDEX($L$3:$L$32,MATCH($G33,$A$3:$A$32,0)),1),0)),IF($H33="",0,IFERROR(WORKDAY(INDEX($L$3:$L$32,MATCH($H33,$A$3:$A$32,0)),1),0))))) | L33: =IF($A33="","",WORKDAY($K33,$I33-1)) | M33: =IF($A33="","",WORKDAY($N33,-($I33-1))) | N33: =IF($A33="","",IF(COUNTIF($F$34:$F$102,$A33)+COUNTIF($G$34:$G$102,$A33)+COUNTIF($H$34:$H$102,$A33)=0,設定!$B$3,MIN(IF(COUNTIF($F$34:$F$102,$A33)=0,999999,IFERROR(WORKDAY(_xlfn.MINIFS($M$34:$M$102,$F$34:$F$102,$A33),-1),999999)),IF(COUNTIF($G$34:$G$102,$A33)=0,999999,IFERROR(WORKDAY(_xlfn.MINIFS($M$34:$M$102,$G$34:$G$102,$A33),-1),999999)),IF(COUNTIF($H$34:$H$102,$A33)=0,999999,IFERROR(WORKDAY(_xlfn.MINIFS($M$34:$M$102,$H$34:$H$102,$A33),-1),999999))))) | O33: =IF($A33="","",NETWORKDAYS($K33,$M33)-1) | P33: =IF($A33="","",IF($O33<=0,"クリティカル","")) | Q33: =IF($A33="","",IF(AND($J33<>"完了",TODAY()>$L33),"遅延","")) | R33: =IF($A33="","",_xlfn.TEXTJOIN(", ",TRUE(),IF($F33="","",IF(IFERROR(INDEX($J$3:$J$102,MATCH($F33,$A$3:$A$102,0)),"")<>"完了",IFERROR(INDEX($C$3:$C$102,MATCH($F33,$A$3:$A$102,0)),""),"")),IF($G33="","",IF(IFERROR(INDEX($J$3:$J$102,MATCH($G33,$A$3:$A$102,0)),"")<>"完了",IFERROR(INDEX($C$3:$C$102,MATCH($G33,$A$3:$A$102,0)),""),"")),IF($H33="","",IF(IFERROR(INDEX($J$3:$J$102,MATCH($H33,$A$3:$A$102,0)),"")<>"完了",IFERROR(INDEX($C$3:$C$102,MATCH($H33,$A$3:$A$102,0)),""),"")))) | S33: =IF($A33="","",IF($J33<>"完了",1,0))
K34: =IF($A34="","",IF(AND($F34="",$G34="",$H34=""),設定!$B$2,MAX(IF($F34="",0,IFERROR(WORKDAY(INDEX($L$3:$L$33,MATCH($F34,$A$3:$A$33,0)),1),0)),IF($G34="",0,IFERROR(WORKDAY(INDEX($L$3:$L$33,MATCH($G34,$A$3:$A$33,0)),1),0)),IF($H34="",0,IFERROR(WORKDAY(INDEX($L$3:$L$33,MATCH($H34,$A$3:$A$33,0)),1),0))))) | L34: =IF($A34="","",WORKDAY($K34,$I34-1)) | M34: =IF($A34="","",WORKDAY($N34,-($I34-1))) | N34: =IF($A34="","",IF(COUNTIF($F$35:$F$102,$A34)+COUNTIF($G$35:$G$102,$A34)+COUNTIF($H$35:$H$102,$A34)=0,設定!$B$3,MIN(IF(COUNTIF($F$35:$F$102,$A34)=0,999999,IFERROR(WORKDAY(_xlfn.MINIFS($M$35:$M$102,$F$35:$F$102,$A34),-1),999999)),IF(COUNTIF($G$35:$G$102,$A34)=0,999999,IFERROR(WORKDAY(_xlfn.MINIFS($M$35:$M$102,$G$35:$G$102,$A34),-1),999999)),IF(COUNTIF($H$35:$H$102,$A34)=0,999999,IFERROR(WORKDAY(_xlfn.MINIFS($M$35:$M$102,$H$35:$H$102,$A34),-1),999999))))) | O34: =IF($A34="","",NETWORKDAYS($K34,$M34)-1) | P34: =IF($A34="","",IF($O34<=0,"クリティカル","")) | Q34: =IF($A34="","",IF(AND($J34<>"完了",TODAY()>$L34),"遅延","")) | R34: =IF($A34="","",_xlfn.TEXTJOIN(", ",TRUE(),IF($F34="","",IF(IFERROR(INDEX($J$3:$J$102,MATCH($F34,$A$3:$A$102,0)),"")<>"完了",IFERROR(INDEX($C$3:$C$102,MATCH($F34,$A$3:$A$102,0)),""),"")),IF($G34="","",IF(IFERROR(INDEX($J$3:$J$102,MATCH($G34,$A$3:$A$102,0)),"")<>"完了",IFERROR(INDEX($C$3:$C$102,MATCH($G34,$A$3:$A$102,0)),""),"")),IF($H34="","",IF(IFERROR(INDEX($J$3:$J$102,MATCH($H34,$A$3:$A$102,0)),"")<>"完了",IFERROR(INDEX($C$3:$C$102,MATCH($H34,$A$3:$A$102,0)),""),"")))) | S34: =IF($A34="","",IF($J34<>"完了",1,0))
K35: =IF($A35="","",IF(AND($F35="",$G35="",$H35=""),設定!$B$2,MAX(IF($F35="",0,IFERROR(WORKDAY(INDEX($L$3:$L$34,MATCH($F35,$A$3:$A$34,0)),1),0)),IF($G35="",0,IFERROR(WORKDAY(INDEX($L$3:$L$34,MATCH($G35,$A$3:$A$34,0)),1),0)),IF($H35="",0,IFERROR(WORKDAY(INDEX($L$3:$L$34,MATCH($H35,$A$3:$A$34,0)),1),0))))) | L35: =IF($A35="","",WORKDAY($K35,$I35-1)) | M35: =IF($A35="","",WORKDAY($N35,-($I35-1))) | N35: =IF($A35="","",IF(COUNTIF($F$36:$F$102,$A35)+COUNTIF($G$36:$G$102,$A35)+COUNTIF($H$36:$H$102,$A35)=0,設定!$B$3,MIN(IF(COUNTIF($F$36:$F$102,$A35)=0,999999,IFERROR(WORKDAY(_xlfn.MINIFS($M$36:$M$102,$F$36:$F$102,$A35),-1),999999)),IF(COUNTIF($G$36:$G$102,$A35)=0,999999,IFERROR(WORKDAY(_xlfn.MINIFS($M$36:$M$102,$G$36:$G$102,$A35),-1),999999)),IF(COUNTIF($H$36:$H$102,$A35)=0,999999,IFERROR(WORKDAY(_xlfn.MINIFS($M$36:$M$102,$H$36:$H$102,$A35),-1),999999))))) | O35: =IF($A35="","",NETWORKDAYS($K35,$M35)-1) | P35: =IF($A35="","",IF($O35<=0,"クリティカル","")) | Q35: =IF($A35="","",IF(AND($J35<>"完了",TODAY()>$L35),"遅延","")) | R35: =IF($A35="","",_xlfn.TEXTJOIN(", ",TRUE(),IF($F35="","",IF(IFERROR(INDEX($J$3:$J$102,MATCH($F35,$A$3:$A$102,0)),"")<>"完了",IFERROR(INDEX($C$3:$C$102,MATCH($F35,$A$3:$A$102,0)),""),"")),IF($G35="","",IF(IFERROR(INDEX($J$3:$J$102,MATCH($G35,$A$3:$A$102,0)),"")<>"完了",IFERROR(INDEX($C$3:$C$102,MATCH($G35,$A$3:$A$102,0)),""),"")),IF($H35="","",IF(IFERROR(INDEX($J$3:$J$102,MATCH($H35,$A$3:$A$102,0)),"")<>"完了",IFERROR(INDEX($C$3:$C$102,MATCH($H35,$A$3:$A$102,0)),""),"")))) | S35: =IF($A35="","",IF($J35<>"完了",1,0))
K36: =IF($A36="","",IF(AND($F36="",$G36="",$H36=""),設定!$B$2,MAX(IF($F36="",0,IFERROR(WORKDAY(INDEX($L$3:$L$35,MATCH($F36,$A$3:$A$35,0)),1),0)),IF($G36="",0,IFERROR(WORKDAY(INDEX($L$3:$L$35,MATCH($G36,$A$3:$A$35,0)),1),0)),IF($H36="",0,IFERROR(WORKDAY(INDEX($L$3:$L$35,MATCH($H36,$A$3:$A$35,0)),1),0))))) | L36: =IF($A36="","",WORKDAY($K36,$I36-1)) | M36: =IF($A36="","",WORKDAY($N36,-($I36-1))) | N36: =IF($A36="","",IF(COUNTIF($F$37:$F$102,$A36)+COUNTIF($G$37:$G$102,$A36)+COUNTIF($H$37:$H$102,$A36)=0,設定!$B$3,MIN(IF(COUNTIF($F$37:$F$102,$A36)=0,999999,IFERROR(WORKDAY(_xlfn.MINIFS($M$37:$M$102,$F$37:$F$102,$A36),-1),999999)),IF(COUNTIF($G$37:$G$102,$A36)=0,999999,IFERROR(WORKDAY(_xlfn.MINIFS($M$37:$M$102,$G$37:$G$102,$A36),-1),999999)),IF(COUNTIF($H$37:$H$102,$A36)=0,999999,IFERROR(WORKDAY(_xlfn.MINIFS($M$37:$M$102,$H$37:$H$102,$A36),-1),999999))))) | O36: =IF($A36="","",NETWORKDAYS($K36,$M36)-1) | P36: =IF($A36="","",IF($O36<=0,"クリティカル","")) | Q36: =IF($A36="","",IF(AND($J36<>"完了",TODAY()>$L36),"遅延","")) | R36: =IF($A36="","",_xlfn.TEXTJOIN(", ",TRUE(),IF($F36="","",IF(IFERROR(INDEX($J$3:$J$102,MATCH($F36,$A$3:$A$102,0)),"")<>"完了",IFERROR(INDEX($C$3:$C$102,MATCH($F36,$A$3:$A$102,0)),""),"")),IF($G36="","",IF(IFERROR(INDEX($J$3:$J$102,MATCH($G36,$A$3:$A$102,0)),"")<>"完了",IFERROR(INDEX($C$3:$C$102,MATCH($G36,$A$3:$A$102,0)),""),"")),IF($H36="","",IF(IFERROR(INDEX($J$3:$J$102,MATCH($H36,$A$3:$A$102,0)),"")<>"完了",IFERROR(INDEX($C$3:$C$102,MATCH($H36,$A$3:$A$102,0)),""),"")))) | S36: =IF($A36="","",IF($J36<>"完了",1,0))
K37: =IF($A37="","",IF(AND($F37="",$G37="",$H37=""),設定!$B$2,MAX(IF($F37="",0,IFERROR(WORKDAY(INDEX($L$3:$L$36,MATCH($F37,$A$3:$A$36,0)),1),0)),IF($G37="",0,IFERROR(WORKDAY(INDEX($L$3:$L$36,MATCH($G37,$A$3:$A$36,0)),1),0)),IF($H37="",0,IFERROR(WORKDAY(INDEX($L$3:$L$36,MATCH($H37,$A$3:$A$36,0)),1),0))))) | L37: =IF($A37="","",WORKDAY($K37,$I37-1)) | M37: =IF($A37="","",WORKDAY($N37,-($I37-1))) | N37: =IF($A37="","",IF(COUNTIF($F$38:$F$102,$A37)+COUNTIF($G$38:$G$102,$A37)+COUNTIF($H$38:$H$102,$A37)=0,設定!$B$3,MIN(IF(COUNTIF($F$38:$F$102,$A37)=0,999999,IFERROR(WORKDAY(_xlfn.MINIFS($M$38:$M$102,$F$38:$F$102,$A37),-1),999999)),IF(COUNTIF($G$38:$G$102,$A37)=0,999999,IFERROR(WORKDAY(_xlfn.MINIFS($M$38:$M$102,$G$38:$G$102,$A37),-1),999999)),IF(COUNTIF($H$38:$H$102,$A37)=0,999999,IFERROR(WORKDAY(_xlfn.MINIFS($M$38:$M$102,$H$38:$H$102,$A37),-1),999999))))) | O37: =IF($A37="","",NETWORKDAYS($K37,$M37)-1) | P37: =IF($A37="","",IF($O37<=0,"クリティカル","")) | Q37: =IF($A37="","",IF(AND($J37<>"完了",TODAY()>$L37),"遅延","")) | R37: =IF($A37="","",_xlfn.TEXTJOIN(", ",TRUE(),IF($F37="","",IF(IFERROR(INDEX($J$3:$J$102,MATCH($F37,$A$3:$A$102,0)),"")<>"完了",IFERROR(INDEX($C$3:$C$102,MATCH($F37,$A$3:$A$102,0)),""),"")),IF($G37="","",IF(IFERROR(INDEX($J$3:$J$102,MATCH($G37,$A$3:$A$102,0)),"")<>"完了",IFERROR(INDEX($C$3:$C$102,MATCH($G37,$A$3:$A$102,0)),""),"")),IF($H37="","",IF(IFERROR(INDEX($J$3:$J$102,MATCH($H37,$A$3:$A$102,0)),"")<>"完了",IFERROR(INDEX($C$3:$C$102,MATCH($H37,$A$3:$A$102,0)),""),"")))) | S37: =IF($A37="","",IF($J37<>"完了",1,0))
K38: =IF($A38="","",IF(AND($F38="",$G38="",$H38=""),設定!$B$2,MAX(IF($F38="",0,IFERROR(WORKDAY(INDEX($L$3:$L$37,MATCH($F38,$A$3:$A$37,0)),1),0)),IF($G38="",0,IFERROR(WORKDAY(INDEX($L$3:$L$37,MATCH($G38,$A$3:$A$37,0)),1),0)),IF($H38="",0,IFERROR(WORKDAY(INDEX($L$3:$L$37,MATCH($H38,$A$3:$A$37,0)),1),0))))) | L38: =IF($A38="","",WORKDAY($K38,$I38-1)) | M38: =IF($A38="","",WORKDAY($N38,-($I38-1))) | N38: =IF($A38="","",IF(COUNTIF($F$39:$F$102,$A38)+COUNTIF($G$39:$G$102,$A38)+COUNTIF($H$39:$H$102,$A38)=0,設定!$B$3,MIN(IF(COUNTIF($F$39:$F$102,$A38)=0,999999,IFERROR(WORKDAY(_xlfn.MINIFS($M$39:$M$102,$F$39:$F$102,$A38),-1),999999)),IF(COUNTIF($G$39:$G$102,$A38)=0,999999,IFERROR(WORKDAY(_xlfn.MINIFS($M$39:$M$102,$G$39:$G$102,$A38),-1),999999)),IF(COUNTIF($H$39:$H$102,$A38)=0,999999,IFERROR(WORKDAY(_xlfn.MINIFS($M$39:$M$102,$H$39:$H$102,$A38),-1),999999))))) | O38: =IF($A38="","",NETWORKDAYS($K38,$M38)-1) | P38: =IF($A38="","",IF($O38<=0,"クリティカル","")) | Q38: =IF($A38="","",IF(AND($J38<>"完了",TODAY()>$L38),"遅延","")) | R38: =IF($A38="","",_xlfn.TEXTJOIN(", ",TRUE(),IF($F38="","",IF(IFERROR(INDEX($J$3:$J$102,MATCH($F38,$A$3:$A$102,0)),"")<>"完了",IFERROR(INDEX($C$3:$C$102,MATCH($F38,$A$3:$A$102,0)),""),"")),IF($G38="","",IF(IFERROR(INDEX($J$3:$J$102,MATCH($G38,$A$3:$A$102,0)),"")<>"完了",IFERROR(INDEX($C$3:$C$102,MATCH($G38,$A$3:$A$102,0)),""),"")),IF($H38="","",IF(IFERROR(INDEX($J$3:$J$102,MATCH($H38,$A$3:$A$102,0)),"")<>"完了",IFERROR(INDEX($C$3:$C$102,MATCH($H38,$A$3:$A$102,0)),""),"")))) | S38: =IF($A38="","",IF($J38<>"完了",1,0))
K39: =IF($A39="","",IF(AND($F39="",$G39="",$H39=""),設定!$B$2,MAX(IF($F39="",0,IFERROR(WORKDAY(INDEX($L$3:$L$38,MATCH($F39,$A$3:$A$38,0)),1),0)),IF($G39="",0,IFERROR(WORKDAY(INDEX($L$3:$L$38,MATCH($G39,$A$3:$A$38,0)),1),0)),IF($H39="",0,IFERROR(WORKDAY(INDEX($L$3:$L$38,MATCH($H39,$A$3:$A$38,0)),1),0))))) | L39: =IF($A39="","",WORKDAY($K39,$I39-1)) | M39: =IF($A39="","",WORKDAY($N39,-($I39-1))) | N39: =IF($A39="","",IF(COUNTIF($F$40:$F$102,$A39)+COUNTIF($G$40:$G$102,$A39)+COUNTIF($H$40:$H$102,$A39)=0,設定!$B$3,MIN(IF(COUNTIF($F$40:$F$102,$A39)=0,999999,IFERROR(WORKDAY(_xlfn.MINIFS($M$40:$M$102,$F$40:$F$102,$A39),-1),999999)),IF(COUNTIF($G$40:$G$102,$A39)=0,999999,IFERROR(WORKDAY(_xlfn.MINIFS($M$40:$M$102,$G$40:$G$102,$A39),-1),999999)),IF(COUNTIF($H$40:$H$102,$A39)=0,999999,IFERROR(WORKDAY(_xlfn.MINIFS($M$40:$M$102,$H$40:$H$102,$A39),-1),999999))))) | O39: =IF($A39="","",NETWORKDAYS($K39,$M39)-1) | P39: =IF($A39="","",IF($O39<=0,"クリティカル","")) | Q39: =IF($A39="","",IF(AND($J39<>"完了",TODAY()>$L39),"遅延","")) | R39: =IF($A39="","",_xlfn.TEXTJOIN(", ",TRUE(),IF($F39="","",IF(IFERROR(INDEX($J$3:$J$102,MATCH($F39,$A$3:$A$102,0)),"")<>"完了",IFERROR(INDEX($C$3:$C$102,MATCH($F39,$A$3:$A$102,0)),""),"")),IF($G39="","",IF(IFERROR(INDEX($J$3:$J$102,MATCH($G39,$A$3:$A$102,0)),"")<>"完了",IFERROR(INDEX($C$3:$C$102,MATCH($G39,$A$3:$A$102,0)),""),"")),IF($H39="","",IF(IFERROR(INDEX($J$3:$J$102,MATCH($H39,$A$3:$A$102,0)),"")<>"完了",IFERROR(INDEX($C$3:$C$102,MATCH($H39,$A$3:$A$102,0)),""),"")))) | S39: =IF($A39="","",IF($J39<>"完了",1,0))
